Workbook

Sheet Dashboard
B2: Planung Stand:
B4: Projekt:
B6: Fördergeber:
B7: Förderprogramm:
B8: Projektträger:
B10: beantragte Fördersumme:
B12: Laufzeitbeginn
B13: Laufzeitende

Sheet Nav
A1: Navigation
H2: Laufzeitbeginn | I2: 45047 | K2: 1. Jahr | O2: =IF(O3="","","2. Jahr") | S2: =IF(S3="","","3. Jahr") | W2: =IF(W3="","","4. Jahr")
C3: Durchführbarkeitsstudie "BioInk" | H3: Laufzeitende | I3: 45289 | K3: =YEAR(L4) -> 2023 | O3: =IF(MONTH(N4)<12,"",IF(YEAR(N4)=YEAR($I$3),"",YEAR(P4))) | S3: =IF(R4="","",IF(MONTH(R4)<12,"",YEAR(T4))) | W3: =IF(V4="","",IF(MONTH(V4)<12,"",YEAR(X4)))
B4: Projekt: | K4: von | L4: =I2 -> 45047 | M4: bis | N4: =DATE(YEAR(I2),12,31) -> 45291 | O4: von | P4: =IF(MONTH(N4)<12,"",IF(YEAR(N4)=YEAR($I$3),"",N4+1)) | Q4: bis | R4: =IF(P4="","",IF(MONTH(N4)<12,"",(IF(YEAR(P4)=YEAR($I$3),$I$3,DATE(YEAR(P4),12,31))))) | S4: von | T4: =IF(R4="","",IF(MONTH(R4)<12,"",R4+1)) | U4: bis | V4: =IF(T4="","",IF(MONTH(R4)<12,"",(IF(YEAR(T4)=YEAR($I$3),$I$3,DATE(YEAR(T4),12,31))))) | W4: von | X4: =IF(V4="","",IF(MONTH(V4)<12,"",V4+1)) | Y4: bis | Z4: =IF(V4="","",IF(MONTH(V4)<12,"",(IF(YEAR(X4)=YEAR($I$3),$I$3,DATE(YEAR(X4),12,31)))))
J5: Eigenanteil: | K5: 0.3 | O5: =K5 -> 0.3 | S5: =O5 -> 0.3 | W5: =IF(W3="-","-",S5) -> 0.3
B6: FKZ: | C6: DS200424 | J6: Bundesanteil: | K6: =1-K5 -> 0.7 | O6: =1-O5 -> 0.7 | S6: =1-S5 -> 0.7 | W6: =IF(W3="-","-",1-W5) -> 0.7
B7: Unternehmen | C7: Tippl GmbH
B8: Anschrift | C8: Im Gehrn 10, 71737 Kirchberg a.d.Murr | J8: Fördersumme PLAN: | K8: =E20 -> 53855 | O8: ='Planung Personal'!AA35 -> 0 | S8: ='Planung Personal'!AA49 -> 0 | W8: ='Planung Personal'!AA63 -> 0 | AA8: =SUM(K8:Z8) -> 53855
B9: Ansprechpartner | C9: Mario Tippl | J9: bisher abgerechet: | K9: ='Ermittl.-Stunden J1'!AF31 -> 54227.311 | O9: ='Auswertung J2'!R66 -> 0 | S9: ='Auswertung J3'!R66 -> 0 | W9: ='Auswertung J4'!R66 -> 0 | AA9: =SUM(K9:Z9) -> 54227.311
B10: Telefon | J10: Differenz: | K10: =K8-K9 -> -372.31087 | O10: =O8-O9 -> 0 | S10: =S8-S9 -> 0 | W10: =W8-W9 -> 0 | AA10: =SUM(K10:Z10) -> -372.31087
B11: Bankverb.
B12: IBAN | I12: Zuschlagsatz: | L12: technisch | M12: 0.2842
B13: BIC | L13: nicht-technisch | M13: 0.2988
I14: Fördermittelabruf
C15: Zuwendungen pro Haushaltsjahr | I15: Plan-Abrechnung | N15: Zuwendungen
B16: =L4 -> 45047 | C16: 20197 | H16: =$L$4 -> 45047 | I16: =E20 -> 53855 | N16: abgerufen | P16: =AA9 -> 54227.311
B17: =IF(C17>0,B16+365,$P$4) -> 45412 | C17: 33658 | H17: =$P$4 | I17: ='Planung Personal'!AA35 -> 0 | N17: verfügbar | P17: =E20-P18-AA9 -> -5757.8109
B18: =IF(C18>0,B17+365,$T$4) | H18: =$T$4 | I18: ='Planung Personal'!AA49 -> 0 | N18: gesperrt | P18: =E20*0.1 -> 5385.5
B19: =IF(C19>0,B18+365,$X$4) | H19: =$X$4 | I19: ='Planung Personal'!AA63 -> 0
C20: Fördersumme gesamt: | E20: =SUM(C16:F19) -> 53855 | I20: =SUM(I16:L19) -> 53855
X22: Projektträger: EURONORM
B23: Personalkosten | I23: Soll-Ist- Auswertung | X23: Anschrift | Z23: Straße | AA23: Stralauer Platz 34
I24: =B16 -> 45047 | Z24: PLZ Ort | AA24: 10243 | AB24: Berlin
B25: Ermittlung Jahresstundennsatz
X26: Ansprechpartner Technik
B27: =B16 -> 45047 | C27: =B17 -> 45412 | D27: =B18 | E27: =B19 | I27: =B17 -> 45412 | Y27: Name:
Y28: E-Mail:
Y29: Telefon:
B31: Stundennachweise | I31: =B18 | X31: Ansprechpartner BWL
B32: Tippl, Mario | C32: =B16 -> 45047 | D32: =B17 -> 45412 | E32: =B18 | F32: =B19 | Y32: Name: | Z32: Dr. Christian Liebold
B33: Socha, Pawel | C33: =B16 -> 45047 | D33: =B17 -> 45412 | E33: =B18 | F33: =B19 | Y33: E-Mail:
B34: Tippl, Karen | C34: =B16 -> 45047 | D34: =B17 -> 45412 | E34: =B18 | F34: =B19 | Y34: Telefon:
B35: MA 4 | C35: =B16 -> 45047 | D35: =B17 -> 45412 | E35: =B18 | F35: =B19 | I35: =B19
B36: MA 5 | C36: =B16 -> 45047 | D36: =B17 -> 45412 | E36: =B18 | F36: =B19

Sheet AP Übersicht
B1: =Nav!C3 -> Durchführbarkeitsstudie "BioInk"
B2: =Nav!C7 -> Tippl GmbH
A4: Arbeitspakete | D4: =Nav!$B$16 -> 45047 | AI4: =Nav!$B$17 -> 45412 | BE4: =Nav!$B$18 | CA4: Arbeitspakete
D5: Realisierungszeitraum | G5: Aufwand NWM | V5: =D4 -> 45047 | AI5: Realisierungszeitraum | AL5: Aufwand NWM | AR5: =AI4 -> 45412 | BE5: Realisierungszeitraum | BH5: Aufwand NWM | BN5: =BE4
A6: Nr. | B6: Arbeitspaket | C6: T | D6: von | E6: bis | F6: Monate | G6: =Nav!$B$32 -> Tippl, Mario | K6: =Nav!$B$33 -> Socha, Pawel | O6: =Nav!$B$34 -> Tippl, Karen | S6: =Nav!$B$35 -> MA 4 | T6: =Nav!$B$36 -> MA 5 | U6: PM | V6: =DATE(YEAR(Nav!$L$4),1,1) -> 44927 | W6: =V6+31 -> 44958 | X6: =IF((MOD(YEAR(W6),4)=0)-(MOD(YEAR(W6),100)=0)+(MOD(YEAR(W6),400)=0)=0,W6+28,W6+29) -> 44986 | Y6: =X6+31 -> 45017 | Z6: =Y6+30 -> 45047 | AA6: =Z6+31 -> 45078 | AB6: =AA6+30 -> 45108 | AC6: =AB6+31 -> 45139 | AD6: =AC6+31 -> 45170 | AE6: =AD6+30 -> 45200 | AF6: =AE6+31 -> 45231 | AG6: =AF6+30 -> 45261 | AI6: von | AJ6: bis | AK6: Monate | AL6: =Nav!$B$32 -> Tippl, Mario | AM6: =Nav!$B$33 -> Socha, Pawel | AN6: =Nav!$B$34 -> Tippl, Karen | AO6: =Nav!$B$35 -> MA 4 | AP6: =Nav!$B$36 -> MA 5 | AQ6: PM | AR6: =AR5 -> 45412 | AS6: =AR6+31 -> 45443 | AT6: =IF((MOD(YEAR(AS6),4)=0)-(MOD(YEAR(AS6),100)=0)+(MOD(YEAR(AS6),400)=0)=0,AS6+28,AS6+29) -> 45472 | AU6: =AT6+31 -> 45503 | AV6: =AU6+30 -> 45533 | AW6: =AV6+31 -> 45564 | AX6: =AW6+30 -> 45594 | AY6: =AX6+31 -> 45625 | AZ6: =AY6+31 -> 45656 | BA6: =AZ6+30 -> 45686 | BB6: =BA6+31 -> 45717 | BC6: =BB6+30 -> 45747 | BE6: von | BF6: bis | BG6: Monate | BH6: =Nav!$B$32 -> Tippl, Mario | BI6: =Nav!$B$33 -> Socha, Pawel | BJ6: =Nav!$B$34 -> Tippl, Karen | BK6: =Nav!$B$35 -> MA 4 | BL6: =Nav!$B$36 -> MA 5 | BM6: PM | BN6: =BN5 | BO6: =BN6+31 -> #VALUE! | BP6: =IF((MOD(YEAR(BO6),4)=0)-(MOD(YEAR(BO6),100)=0)+(MOD(YEAR(BO6),400)=0)=0,BO6+28,BO6+29) -> #VALUE! | BQ6: =BP6+31 -> #VALUE! | BR6: =BQ6+30 -> #VALUE! | BS6: =BR6+31 -> #VALUE! | BT6: =BS6+30 -> #VALUE! | BU6: =BT6+31 -> #VALUE! | BV6: =BU6+31 -> #VALUE! | BW6: =BV6+30 -> #VALUE! | BX6: =BW6+31 -> #VALUE! | BY6: =BX6+30 -> #VALUE! | CA6: Nr. | CB6: Arbeitspaket
G7: ='Planung Personal'!$T$9/12 -> 10000 | H7: h | I7: ZA | J7: offen | K7: ='Planung Personal'!$T$11/12 -> 3225 | L7: h | M7: ZA | N7: offen | O7: ='Planung Personal'!$T$13/12 -> 2975 | P7: h | Q7: ZA | R7: offen | S7: ='Planung Personal'!$T$15/12 -> 0 | T7: ='Planung Personal'!$T$17/12 -> 0 | AL7: ='Planung Personal'!$T$9/12 -> 10000 | AM7: ='Planung Personal'!$T$11/12 -> 3225 | AN7: ='Planung Personal'!$T$13/12 -> 2975 | AO7: ='Planung Personal'!$T$15/12 -> 0 | AP7: ='Planung Personal'!$T$17/12 -> 0 | BH7: ='Planung Personal'!$T$9/12 -> 10000 | BI7: ='Planung Personal'!$T$11/12 -> 3225 | BJ7: ='Planung Personal'!$T$13/12 -> 2975 | BK7: ='Planung Personal'!$T$15/12 -> 0 | BL7: ='Planung Personal'!$T$17/12 -> 0
A8: 1 | B8: Analyse Stand der Technik | D8: 45047 | E8: 45077 | F8: =IF(D8="","",ROUND((E8-D8)/30,0)) -> 1 | G8: 0.5 | H8: =$G8*'Ermittl.-Stunden J1'!$T$5 -> 86.666667 | I8: =SUMIF('Tippl M. J1'!$B$17:$AK$511,'AP Übersicht'!$A8,'Tippl M. J1'!$AK$17:$AK$511) -> 86.67 | J8: =H8-I8 -> -0.0033333333 | L8: =$K8*'Ermittl.-Stunden J1'!$T$15 -> 0 | M8: =SUMIF('Socha J1'!$B$17:$AK$511,'AP Übersicht'!$A8,'Socha J1'!$AK$17:$AK$511) -> 0 | N8: =L8-M8 -> 0 | P8: =$O8*'Ermittl.-Stunden J1'!$T$25 -> 0 | Q8: =SUMIF('Tippl K. J1'!$B$17:$AK$511,'AP Übersicht'!$A8,'Tippl K. J1'!$AK$17:$AK$511) -> 0 | R8: =P8-Q8 -> 0 | U8: =SUM(G8,K8,O8) -> 0.5 | V8: =IF(AND(V$6>=$D8,V$6<=$E8),"x","") | W8: =IF(AND(W$6>=$D8,W$6<=$E8),"x","") | X8: =IF(AND(X$6>=$D8,X$6<=$E8),"x","") | Y8: =IF(AND(Y$6>=$D8,Y$6<=$E8),"x","") | Z8: =IF(AND(Z$6>=$D8,Z$6<=$E8),"x","") -> x | AA8: =IF(AND(AA$6>=$D8,AA$6<=$E8),"x","") | AB8: =IF(AND(AB$6>=$D8,AB$6<=$E8),"x","") | AC8: =IF(AND(AC$6>=$D8,AC$6<=$E8),"x","") | ... AG8: =IF(AND(AG$6>=$D8,AG$6<=$E8),"x","") | AK8: =IF(AI8="","",ROUND((AJ8-AI8)/30,0)) | AQ8: =SUM(AL8:AP8) -> 0 | AR8: =IF(AND(AR$6>=$AI8,AR$6<=$AJ8),"x","") | AS8: =IF(AND(AS$6>=$AI8,AS$6<=$AJ8),"x","") | AT8: =IF(AND(AT$6>=$AI8,AT$6<=$AJ8),"x","") | AU8: =IF(AND(AU$6>=$AI8,AU$6<=$AJ8),"x","") | AV8: =IF(AND(AV$6>=$AI8,AV$6<=$AJ8),"x","") | AW8: =IF(AND(AW$6>=$AI8,AW$6<=$AJ8),"x","") | AX8: =IF(AND(AX$6>=$AI8,AX$6<=$AJ8),"x","") | AY8: =IF(AND(AY$6>=$AI8,AY$6<=$AJ8),"x","") | ... BC8: =IF(AND(BC$6>=$AI8,BC$6<=$AJ8),"x","") | BG8: =IF(BE8="","",ROUND((BF8-BE8)/30,0)) | BM8: =SUM(BH8:BL8) -> 0 | BN8: =IF(AND(BN$6>=$BE8,BN$6<=$BF8),"x","") -> x | BO8: =IF(AND(BO$6>=$BE8,BO$6<=$BF8),"x","") -> #VALUE! | BP8: =IF(AND(BP$6>=$BE8,BP$6<=$BF8),"x","") -> #VALUE! | BQ8: =IF(AND(BQ$6>=$BE8,BQ$6<=$BF8),"x","") -> #VALUE! | BR8: =IF(AND(BR$6>=$BE8,BR$6<=$BF8),"x","") -> #VALUE! | BS8: =IF(AND(BS$6>=$BE8,BS$6<=$BF8),"x","") -> #VALUE! | BT8: =IF(AND(BT$6>=$BE8,BT$6<=$BF8),"x","") -> #VALUE! | BU8: =IF(AND(BU$6>=$BE8,BU$6<=$BF8),"x","") -> #VALUE! | ... BY8: =IF(AND(BY$6>=$BE8,BY$6<=$BF8),"x","") -> #VALUE! | CA8: =A8 -> 1 | CB8: =B8 -> Analyse Stand der Technik
A9: 2.1 | D9: 45047 | E9: 45077 | F9: =IF(D9="","",ROUND((E9-D9)/30,0)) -> 1 | H9: =$G9*'Ermittl.-Stunden J1'!$T$5 -> 0 | I9: =SUMIF('Tippl M. J1'!$B$17:$AK$511,'AP Übersicht'!$A9,'Tippl M. J1'!$AK$17:$AK$511) -> 0 | J9: =H9-I9 -> 0 | L9: =$K9*'Ermittl.-Stunden J1'!$T$15 -> 0 | M9: =SUMIF('Socha J1'!$B$17:$AK$511,'AP Übersicht'!$A9,'Socha J1'!$AK$17:$AK$511) -> 0 | N9: =L9-M9 -> 0 | P9: =$O9*'Ermittl.-Stunden J1'!$T$25 -> 0 | Q9: =SUMIF('Tippl K. J1'!$B$17:$AK$511,'AP Übersicht'!$A9,'Tippl K. J1'!$AK$17:$AK$511) -> 0 | R9: =P9-Q9 -> 0 | U9: =SUM(G9,K9,O9) -> 0 | V9: =IF(AND(V$6>=$D9,V$6<=$E9),"x","") | W9: =IF(AND(W$6>=$D9,W$6<=$E9),"x","") | X9: =IF(AND(X$6>=$D9,X$6<=$E9),"x","") | Y9: =IF(AND(Y$6>=$D9,Y$6<=$E9),"x","") | Z9: =IF(AND(Z$6>=$D9,Z$6<=$E9),"x","") -> x | AA9: =IF(AND(AA$6>=$D9,AA$6<=$E9),"x","") | AB9: =IF(AND(AB$6>=$D9,AB$6<=$E9),"x","") | AC9: =IF(AND(AC$6>=$D9,AC$6<=$E9),"x","") | ... AG9: =IF(AND(AG$6>=$D9,AG$6<=$E9),"x","") | AK9: =IF(AI9="","",ROUND((AJ9-AI9)/30,0)) | AQ9: =SUM(AL9:AP9) -> 0 | AR9: =IF(AND(AR$6>=$AI9,AR$6<=$AJ9),"x","") | AS9: =IF(AND(AS$6>=$AI9,AS$6<=$AJ9),"x","") | AT9: =IF(AND(AT$6>=$AI9,AT$6<=$AJ9),"x","") | AU9: =IF(AND(AU$6>=$AI9,AU$6<=$AJ9),"x","") | AV9: =IF(AND(AV$6>=$AI9,AV$6<=$AJ9),"x","") | AW9: =IF(AND(AW$6>=$AI9,AW$6<=$AJ9),"x","") | AX9: =IF(AND(AX$6>=$AI9,AX$6<=$AJ9),"x","") | AY9: =IF(AND(AY$6>=$AI9,AY$6<=$AJ9),"x","") | ... BC9: =IF(AND(BC$6>=$AI9,BC$6<=$AJ9),"x","") | BG9: =IF(BE9="","",ROUND((BF9-BE9)/30,0)) | BM9: =SUM(BH9:BL9) -> 0 | BN9: =IF(AND(BN$6>=$BE9,BN$6<=$BF9),"x","") -> x | BO9: =IF(AND(BO$6>=$BE9,BO$6<=$BF9),"x","") -> #VALUE! | BP9: =IF(AND(BP$6>=$BE9,BP$6<=$BF9),"x","") -> #VALUE! | BQ9: =IF(AND(BQ$6>=$BE9,BQ$6<=$BF9),"x","") -> #VALUE! | BR9: =IF(AND(BR$6>=$BE9,BR$6<=$BF9),"x","") -> #VALUE! | BS9: =IF(AND(BS$6>=$BE9,BS$6<=$BF9),"x","") -> #VALUE! | BT9: =IF(AND(BT$6>=$BE9,BT$6<=$BF9),"x","") -> #VALUE! | BU9: =IF(AND(BU$6>=$BE9,BU$6<=$BF9),"x","") -> #VALUE! | ... BY9: =IF(AND(BY$6>=$BE9,BY$6<=$BF9),"x","") -> #VALUE! | CA9: =A9 -> 2.1 | CB9: =B9 -> 0
A10: 2.2 | B10: Analyse Marktpotential/Patentprüfung | D10: 45047 | E10: 45077 | F10: =IF(D10="","",ROUND((E10-D10)/30,0)) -> 1 | H10: =$G10*'Ermittl.-Stunden J1'!$T$5 -> 0 | I10: =SUMIF('Tippl M. J1'!$B$17:$AK$511,'AP Übersicht'!$A10,'Tippl M. J1'!$AK$17:$AK$511) -> 0 | J10: =H10-I10 -> 0 | K10: 0.5 | L10: =$K10*'Ermittl.-Stunden J1'!$T$15 -> 86.666667 | M10: =SUMIF('Socha J1'!$B$17:$AK$511,'AP Übersicht'!$A10,'Socha J1'!$AK$17:$AK$511) -> 86.67 | N10: =L10-M10 -> -0.0033333333 | P10: =$O10*'Ermittl.-Stunden J1'!$T$25 -> 0 | Q10: =SUMIF('Tippl K. J1'!$B$17:$AK$511,'AP Übersicht'!$A10,'Tippl K. J1'!$AK$17:$AK$511) -> 86.67 | R10: =P10-Q10 -> -86.67 | U10: =SUM(G10,K10,O10) -> 0.5 | V10: =IF(AND(V$6>=$D10,V$6<=$E10),"x","") | W10: =IF(AND(W$6>=$D10,W$6<=$E10),"x","") | X10: =IF(AND(X$6>=$D10,X$6<=$E10),"x","") | Y10: =IF(AND(Y$6>=$D10,Y$6<=$E10),"x","") | Z10: =IF(AND(Z$6>=$D10,Z$6<=$E10),"x","") -> x | AA10: =IF(AND(AA$6>=$D10,AA$6<=$E10),"x","") | AB10: =IF(AND(AB$6>=$D10,AB$6<=$E10),"x","") | AC10: =IF(AND(AC$6>=$D10,AC$6<=$E10),"x","") | ... AG10: =IF(AND(AG$6>=$D10,AG$6<=$E10),"x","") | AK10: =IF(AI10="","",ROUND((AJ10-AI10)/30,0)) | AQ10: =SUM(AL10:AP10) -> 0 | AR10: =IF(AND(AR$6>=$AI10,AR$6<=$AJ10),"x","") | AS10: =IF(AND(AS$6>=$AI10,AS$6<=$AJ10),"x","") | AT10: =IF(AND(AT$6>=$AI10,AT$6<=$AJ10),"x","") | AU10: =IF(AND(AU$6>=$AI10,AU$6<=$AJ10),"x","") | AV10: =IF(AND(AV$6>=$AI10,AV$6<=$AJ10),"x","") | AW10: =IF(AND(AW$6>=$AI10,AW$6<=$AJ10),"x","") | AX10: =IF(AND(AX$6>=$AI10,AX$6<=$AJ10),"x","") | AY10: =IF(AND(AY$6>=$AI10,AY$6<=$AJ10),"x","") | ... BC10: =IF(AND(BC$6>=$AI10,BC$6<=$AJ10),"x","") | BG10: =IF(BE10="","",ROUND((BF10-BE10)/30,0)) | BM10: =SUM(BH10:BL10) -> 0 | BN10: =IF(AND(BN$6>=$BE10,BN$6<=$BF10),"x","") -> x | BO10: =IF(AND(BO$6>=$BE10,BO$6<=$BF10),"x","") -> #VALUE! | BP10: =IF(AND(BP$6>=$BE10,BP$6<=$BF10),"x","") -> #VALUE! | BQ10: =IF(AND(BQ$6>=$BE10,BQ$6<=$BF10),"x","") -> #VALUE! | BR10: =IF(AND(BR$6>=$BE10,BR$6<=$BF10),"x","") -> #VALUE! | BS10: =IF(AND(BS$6>=$BE10,BS$6<=$BF10),"x","") -> #VALUE! | BT10: =IF(AND(BT$6>=$BE10,BT$6<=$BF10),"x","") -> #VALUE! | BU10: =IF(AND(BU$6>=$BE10,BU$6<=$BF10),"x","") -> #VALUE! | ... BY10: =IF(AND(BY$6>=$BE10,BY$6<=$BF10),"x","") -> #VALUE! | CA10: =A10 -> 2.2 | CB10: =B10 -> Analyse Marktpotential/Patentprüfung
A11: 3 | B11: Erstellung AP für FuE-Projekt | D11: 45231 | E11: 45260 | F11: =IF(D11="","",ROUND((E11-D11)/30,0)) -> 1 | G11: 0.5 | H11: =$G11*'Ermittl.-Stunden J1'!$T$5 -> 86.666667 | I11: =SUMIF('Tippl M. J1'!$B$17:$AK$511,'AP Übersicht'!$A11,'Tippl M. J1'!$AK$17:$AK$511) -> 21 | J11: =H11-I11 -> 65.666667 | L11: =$K11*'Ermittl.-Stunden J1'!$T$15 -> 0 | M11: =SUMIF('Socha J1'!$B$17:$AK$511,'AP Übersicht'!$A11,'Socha J1'!$AK$17:$AK$511) -> 7.5 | N11: =L11-M11 -> -7.5 | P11: =$O11*'Ermittl.-Stunden J1'!$T$25 -> 0 | Q11: =SUMIF('Tippl K. J1'!$B$17:$AK$511,'AP Übersicht'!$A11,'Tippl K. J1'!$AK$17:$AK$511) -> 0 | R11: =P11-Q11 -> 0 | U11: =SUM(G11,K11,O11) -> 0.5 | V11: =IF(AND(V$6>=$D11,V$6<=$E11),"x","") | W11: =IF(AND(W$6>=$D11,W$6<=$E11),"x","") | X11: =IF(AND(X$6>=$D11,X$6<=$E11),"x","") | Y11: =IF(AND(Y$6>=$D11,Y$6<=$E11),"x","") | Z11: =IF(AND(Z$6>=$D11,Z$6<=$E11),"x","") | AA11: =IF(AND(AA$6>=$D11,AA$6<=$E11),"x","") | AB11: =IF(AND(AB$6>=$D11,AB$6<=$E11),"x","") | AC11: =IF(AND(AC$6>=$D11,AC$6<=$E11),"x","") | ... AG11: =IF(AND(AG$6>=$D11,AG$6<=$E11),"x","") | AK11: =IF(AI11="","",ROUND((AJ11-AI11)/30,0)) | AQ11: =SUM(AL11:AP11) -> 0 | AR11: =IF(AND(AR$6>=$AI11,AR$6<=$AJ11),"x","") | AS11: =IF(AND(AS$6>=$AI11,AS$6<=$AJ11),"x","") | AT11: =IF(AND(AT$6>=$AI11,AT$6<=$AJ11),"x","") | AU11: =IF(AND(AU$6>=$AI11,AU$6<=$AJ11),"x","") | AV11: =IF(AND(AV$6>=$AI11,AV$6<=$AJ11),"x","") | AW11: =IF(AND(AW$6>=$AI11,AW$6<=$AJ11),"x","") | AX11: =IF(AND(AX$6>=$AI11,AX$6<=$AJ11),"x","") | AY11: =IF(AND(AY$6>=$AI11,AY$6<=$AJ11),"x","") | ... BC11: =IF(AND(BC$6>=$AI11,BC$6<=$AJ11),"x","") | BG11: =IF(BE11="","",ROUND((BF11-BE11)/30,0)) | BM11: =SUM(BH11:BL11) -> 0 | BN11: =IF(AND(BN$6>=$BE11,BN$6<=$BF11),"x","") -> x | BO11: =IF(AND(BO$6>=$BE11,BO$6<=$BF11),"x","") -> #VALUE! | BP11: =IF(AND(BP$6>=$BE11,BP$6<=$BF11),"x","") -> #VALUE! | BQ11: =IF(AND(BQ$6>=$BE11,BQ$6<=$BF11),"x","") -> #VALUE! | BR11: =IF(AND(BR$6>=$BE11,BR$6<=$BF11),"x","") -> #VALUE! | BS11: =IF(AND(BS$6>=$BE11,BS$6<=$BF11),"x","") -> #VALUE! | BT11: =IF(AND(BT$6>=$BE11,BT$6<=$BF11),"x","") -> #VALUE! | BU11: =IF(AND(BU$6>=$BE11,BU$6<=$BF11),"x","") -> #VALUE! | ... BY11: =IF(AND(BY$6>=$BE11,BY$6<=$BF11),"x","") -> #VALUE! | CA11: =A11 -> 3 | CB11: =B11 -> Erstellung AP für FuE-Projekt
A12: 4.1 | B12: Recherche und Anforderungen an biobasierte Lösemittel, deren Parameter und Einsatzfähigkeit in Markierungs- und Kennzeichnungssystemen | C12: x | D12: 45078 | E12: 45107 | F12: =IF(D12="","",ROUND((E12-D12)/30,0)) -> 1 | G12: 0.5 | H12: =$G12*'Ermittl.-Stunden J1'!$T$5 -> 86.666667 | I12: =SUMIF('Tippl M. J1'!$B$17:$AK$511,'AP Übersicht'!$A12,'Tippl M. J1'!$AK$17:$AK$511) -> 86.666 | J12: =H12-I12 -> 0.00066666667 | L12: =$K12*'Ermittl.-Stunden J1'!$T$15 -> 0 | M12: =SUMIF('Socha J1'!$B$17:$AK$511,'AP Übersicht'!$A12,'Socha J1'!$AK$17:$AK$511) -> 173.33 | N12: =L12-M12 -> -173.33 | O12: 0.5 | P12: =$O12*'Ermittl.-Stunden J1'!$T$25 -> 43.333333 | Q12: =SUMIF('Tippl K. J1'!$B$17:$AK$511,'AP Übersicht'!$A12,'Tippl K. J1'!$AK$17:$AK$511) -> 106.66 | R12: =P12-Q12 -> -63.326667 | U12: =SUM(G12,K12,O12) -> 1 | V12: =IF(AND(V$6>=$D12,V$6<=$E12),"x","") | W12: =IF(AND(W$6>=$D12,W$6<=$E12),"x","") | X12: =IF(AND(X$6>=$D12,X$6<=$E12),"x","") | Y12: =IF(AND(Y$6>=$D12,Y$6<=$E12),"x","") | Z12: =IF(AND(Z$6>=$D12,Z$6<=$E12),"x","") | AA12: =IF(AND(AA$6>=$D12,AA$6<=$E12),"x","") -> x | AB12: =IF(AND(AB$6>=$D12,AB$6<=$E12),"x","") | AC12: =IF(AND(AC$6>=$D12,AC$6<=$E12),"x","") | ... AG12: =IF(AND(AG$6>=$D12,AG$6<=$E12),"x","") | AK12: =IF(AI12="","",ROUND((AJ12-AI12)/30,0)) | AQ12: =SUM(AL12:AP12) -> 0 | AR12: =IF(AND(AR$6>=$AI12,AR$6<=$AJ12),"x","") | AS12: =IF(AND(AS$6>=$AI12,AS$6<=$AJ12),"x","") | AT12: =IF(AND(AT$6>=$AI12,AT$6<=$AJ12),"x","") | AU12: =IF(AND(AU$6>=$AI12,AU$6<=$AJ12),"x","") | AV12: =IF(AND(AV$6>=$AI12,AV$6<=$AJ12),"x","") | AW12: =IF(AND(AW$6>=$AI12,AW$6<=$AJ12),"x","") | AX12: =IF(AND(AX$6>=$AI12,AX$6<=$AJ12),"x","") | AY12: =IF(AND(AY$6>=$AI12,AY$6<=$AJ12),"x","") | ... BC12: =IF(AND(BC$6>=$AI12,BC$6<=$AJ12),"x","") | BG12: =IF(BE12="","",ROUND((BF12-BE12)/30,0)) | BM12: =SUM(BH12:BL12) -> 0 | BN12: =IF(AND(BN$6>=$BE12,BN$6<=$BF12),"x","") -> x | BO12: =IF(AND(BO$6>=$BE12,BO$6<=$BF12),"x","") -> #VALUE! | BP12: =IF(AND(BP$6>=$BE12,BP$6<=$BF12),"x","") -> #VALUE! | BQ12: =IF(AND(BQ$6>=$BE12,BQ$6<=$BF12),"x","") -> #VALUE! | BR12: =IF(AND(BR$6>=$BE12,BR$6<=$BF12),"x","") -> #VALUE! | BS12: =IF(AND(BS$6>=$BE12,BS$6<=$BF12),"x","") -> #VALUE! | BT12: =IF(AND(BT$6>=$BE12,BT$6<=$BF12),"x","") -> #VALUE! | BU12: =IF(AND(BU$6>=$BE12,BU$6<=$BF12),"x","") -> #VALUE! | ... BY12: =IF(AND(BY$6>=$BE12,BY$6<=$BF12),"x","") -> #VALUE! | CA12: =A12 -> 4.1 | CB12: =B12 -> Recherche und Anforderungen an biobasierte Lösemittel, deren Parameter und Einsatzfähigkeit in Markierungs- und Kennzeichnungssystemen
A13: 4.2 | B13: Beschaffung verfügbarer biobasierter Lösemittel sowie Versuche zur Herstellung von Tinten mit diesen Rohstoffen | C13: x | D13: 45108 | E13: 45169 | F13: =IF(D13="","",ROUND((E13-D13)/30,0)) -> 2 | G13: 1 | H13: =$G13*'Ermittl.-Stunden J1'!$T$5 -> 173.33333 | I13: =SUMIF('Tippl M. J1'!$B$17:$AK$511,'AP Übersicht'!$A13,'Tippl M. J1'!$AK$17:$AK$511) -> 127.33 | J13: =H13-I13 -> 46.003333 | K13: 1 | L13: =$K13*'Ermittl.-Stunden J1'!$T$15 -> 173.33333 | M13: =SUMIF('Socha J1'!$B$17:$AK$511,'AP Übersicht'!$A13,'Socha J1'!$AK$17:$AK$511) -> 132.67 | N13: =L13-M13 -> 40.663333 | O13: 1 | P13: =$O13*'Ermittl.-Stunden J1'!$T$25 -> 86.666667 | Q13: =SUMIF('Tippl K. J1'!$B$17:$AK$511,'AP Übersicht'!$A13,'Tippl K. J1'!$AK$17:$AK$511) -> 18.67 | R13: =P13-Q13 -> 67.996667 | U13: =SUM(G13,K13,O13) -> 3 | V13: =IF(AND(V$6>=$D13,V$6<=$E13),"x","") | W13: =IF(AND(W$6>=$D13,W$6<=$E13),"x","") | X13: =IF(AND(X$6>=$D13,X$6<=$E13),"x","") | Y13: =IF(AND(Y$6>=$D13,Y$6<=$E13),"x","") | Z13: =IF(AND(Z$6>=$D13,Z$6<=$E13),"x","") | AA13: =IF(AND(AA$6>=$D13,AA$6<=$E13),"x","") | AB13: =IF(AND(AB$6>=$D13,AB$6<=$E13),"x","") -> x | AC13: =IF(AND(AC$6>=$D13,AC$6<=$E13),"x","") -> x | ... AG13: =IF(AND(AG$6>=$D13,AG$6<=$E13),"x","") | AK13: =IF(AI13="","",ROUND((AJ13-AI13)/30,0)) | AQ13: =SUM(AL13:AP13) -> 0 | AR13: =IF(AND(AR$6>=$AI13,AR$6<=$AJ13),"x","") | AS13: =IF(AND(AS$6>=$AI13,AS$6<=$AJ13),"x","") | AT13: =IF(AND(AT$6>=$AI13,AT$6<=$AJ13),"x","") | AU13: =IF(AND(AU$6>=$AI13,AU$6<=$AJ13),"x","") | AV13: =IF(AND(AV$6>=$AI13,AV$6<=$AJ13),"x","") | AW13: =IF(AND(AW$6>=$AI13,AW$6<=$AJ13),"x","") | AX13: =IF(AND(AX$6>=$AI13,AX$6<=$AJ13),"x","") | AY13: =IF(AND(AY$6>=$AI13,AY$6<=$AJ13),"x","") | ... BC13: =IF(AND(BC$6>=$AI13,BC$6<=$AJ13),"x","") | BG13: =IF(BE13="","",ROUND((BF13-BE13)/30,0)) | BM13: =SUM(BH13:BL13) -> 0 | BN13: =IF(AND(BN$6>=$BE13,BN$6<=$BF13),"x","") -> x | BO13: =IF(AND(BO$6>=$BE13,BO$6<=$BF13),"x","") -> #VALUE! | BP13: =IF(AND(BP$6>=$BE13,BP$6<=$BF13),"x","") -> #VALUE! | BQ13: =IF(AND(BQ$6>=$BE13,BQ$6<=$BF13),"x","") -> #VALUE! | BR13: =IF(AND(BR$6>=$BE13,BR$6<=$BF13),"x","") -> #VALUE! | BS13: =IF(AND(BS$6>=$BE13,BS$6<=$BF13),"x","") -> #VALUE! | BT13: =IF(AND(BT$6>=$BE13,BT$6<=$BF13),"x","") -> #VALUE! | BU13: =IF(AND(BU$6>=$BE13,BU$6<=$BF13),"x","") -> #VALUE! | ... BY13: =IF(AND(BY$6>=$BE13,BY$6<=$BF13),"x","") -> #VALUE! | CA13: =A13 -> 4.2 | CB13: =B13 -> Beschaffung verfügbarer biobasierter Lösemittel sowie Versuche zur Herstellung von Tinten mit diesen Rohstoffen
A14: 4.3 | B14: Versuche zur Einsatzfähigkeit und den Parametern (aufzutragende Menge, Temperatur, relative Luftfeuchtigkeit bzw. zum Einsatzbereich im industriellen Umfeld | C14: x | D14: 45170 | E14: 45230 | F14: =IF(D14="","",ROUND((E14-D14)/30,0)) -> 2 | G14: 1 | H14: =$G14*'Ermittl.-Stunden J1'!$T$5 -> 173.33333 | I14: =SUMIF('Tippl M. J1'!$B$17:$AK$511,'AP Übersicht'!$A14,'Tippl M. J1'!$AK$17:$AK$511) -> 264.67 | J14: =H14-I14 -> -91.336667 | L14: =$K14*'Ermittl.-Stunden J1'!$T$15 -> 0 | M14: =SUMIF('Socha J1'!$B$17:$AK$511,'AP Übersicht'!$A14,'Socha J1'!$AK$17:$AK$511) -> 152 | N14: =L14-M14 -> -152 | O14: 1 | P14: =$O14*'Ermittl.-Stunden J1'!$T$25 -> 86.666667 | Q14: =SUMIF('Tippl K. J1'!$B$17:$AK$511,'AP Übersicht'!$A14,'Tippl K. J1'!$AK$17:$AK$511) -> 148 | R14: =P14-Q14 -> -61.333333 | U14: =SUM(G14,K14,O14) -> 2 | V14: =IF(AND(V$6>=$D14,V$6<=$E14),"x","") | W14: =IF(AND(W$6>=$D14,W$6<=$E14),"x","") | X14: =IF(AND(X$6>=$D14,X$6<=$E14),"x","") | Y14: =IF(AND(Y$6>=$D14,Y$6<=$E14),"x","") | Z14: =IF(AND(Z$6>=$D14,Z$6<=$E14),"x","") | AA14: =IF(AND(AA$6>=$D14,AA$6<=$E14),"x","") | AB14: =IF(AND(AB$6>=$D14,AB$6<=$E14),"x","") | AC14: =IF(AND(AC$6>=$D14,AC$6<=$E14),"x","") | ... AG14: =IF(AND(AG$6>=$D14,AG$6<=$E14),"x","") | AK14: =IF(AI14="","",ROUND((AJ14-AI14)/30,0)) | AQ14: =SUM(AL14:AP14) -> 0 | AR14: =IF(AND(AR$6>=$AI14,AR$6<=$AJ14),"x","") | AS14: =IF(AND(AS$6>=$AI14,AS$6<=$AJ14),"x","") | AT14: =IF(AND(AT$6>=$AI14,AT$6<=$AJ14),"x","") | AU14: =IF(AND(AU$6>=$AI14,AU$6<=$AJ14),"x","") | AV14: =IF(AND(AV$6>=$AI14,AV$6<=$AJ14),"x","") | AW14: =IF(AND(AW$6>=$AI14,AW$6<=$AJ14),"x","") | AX14: =IF(AND(AX$6>=$AI14,AX$6<=$AJ14),"x","") | AY14: =IF(AND(AY$6>=$AI14,AY$6<=$AJ14),"x","") | ... BC14: =IF(AND(BC$6>=$AI14,BC$6<=$AJ14),"x","") | BG14: =IF(BE14="","",ROUND((BF14-BE14)/30,0)) | BM14: =SUM(BH14:BL14) -> 0 | BN14: =IF(AND(BN$6>=$BE14,BN$6<=$BF14),"x","") -> x | BO14: =IF(AND(BO$6>=$BE14,BO$6<=$BF14),"x","") -> #VALUE! | BP14: =IF(AND(BP$6>=$BE14,BP$6<=$BF14),"x","") -> #VALUE! | BQ14: =IF(AND(BQ$6>=$BE14,BQ$6<=$BF14),"x","") -> #VALUE! | BR14: =IF(AND(BR$6>=$BE14,BR$6<=$BF14),"x","") -> #VALUE! | BS14: =IF(AND(BS$6>=$BE14,BS$6<=$BF14),"x","") -> #VALUE! | BT14: =IF(AND(BT$6>=$BE14,BT$6<=$BF14),"x","") -> #VALUE! | BU14: =IF(AND(BU$6>=$BE14,BU$6<=$BF14),"x","") -> #VALUE! | ... BY14: =IF(AND(BY$6>=$BE14,BY$6<=$BF14),"x","") -> #VALUE! | CA14: =A14 -> 4.3 | CB14: =B14 -> Versuche zur Einsatzfähigkeit und den Parametern (aufzutragende Menge, Temperatur, relative Luftfeuchtigkeit bzw. zum Einsatzbereich im industriellen Umfeld
A15: 5 | B15: Ermittl. wissenschaftlich-technischer Ressourcen und möglicher Kooperationspartner | D15: 45231 | E15: 45289 | F15: =IF(D15="","",ROUND((E15-D15)/30,0)) -> 2 | G15: 0.5 | H15: =$G15*'Ermittl.-Stunden J1'!$T$5 -> 86.666667 | I15: =SUMIF('Tippl M. J1'!$B$17:$AK$511,'AP Übersicht'!$A15,'Tippl M. J1'!$AK$17:$AK$511) -> 59 | J15: =H15-I15 -> 27.666667 | L15: =$K15*'Ermittl.-Stunden J1'!$T$15 -> 0 | M15: =SUMIF('Socha J1'!$B$17:$AK$511,'AP Übersicht'!$A15,'Socha J1'!$AK$17:$AK$511) -> 0 | N15: =L15-M15 -> 0 | P15: =$O15*'Ermittl.-Stunden J1'!$T$25 -> 0 | Q15: =SUMIF('Tippl K. J1'!$B$17:$AK$511,'AP Übersicht'!$A15,'Tippl K. J1'!$AK$17:$AK$511) -> 0 | R15: =P15-Q15 -> 0 | U15: =SUM(G15,K15,O15) -> 0.5 | V15: =IF(AND(V$6>=$D15,V$6<=$E15),"x","") | W15: =IF(AND(W$6>=$D15,W$6<=$E15),"x","") | X15: =IF(AND(X$6>=$D15,X$6<=$E15),"x","") | Y15: =IF(AND(Y$6>=$D15,Y$6<=$E15),"x","") | Z15: =IF(AND(Z$6>=$D15,Z$6<=$E15),"x","") | AA15: =IF(AND(AA$6>=$D15,AA$6<=$E15),"x","") | AB15: =IF(AND(AB$6>=$D15,AB$6<=$E15),"x","") | AC15: =IF(AND(AC$6>=$D15,AC$6<=$E15),"x","") | ... AG15: =IF(AND(AG$6>=$D15,AG$6<=$E15),"x","") -> x | AK15: =IF(AI15="","",ROUND((AJ15-AI15)/30,0)) | AQ15: =SUM(AL15:AP15) -> 0 | AR15: =IF(AND(AR$6>=$AI15,AR$6<=$AJ15),"x","") | AS15: =IF(AND(AS$6>=$AI15,AS$6<=$AJ15),"x","") | AT15: =IF(AND(AT$6>=$AI15,AT$6<=$AJ15),"x","") | AU15: =IF(AND(AU$6>=$AI15,AU$6<=$AJ15),"x","") | AV15: =IF(AND(AV$6>=$AI15,AV$6<=$AJ15),"x","") | AW15: =IF(AND(AW$6>=$AI15,AW$6<=$AJ15),"x","") | AX15: =IF(AND(AX$6>=$AI15,AX$6<=$AJ15),"x","") | AY15: =IF(AND(AY$6>=$AI15,AY$6<=$AJ15),"x","") | ... BC15: =IF(AND(BC$6>=$AI15,BC$6<=$AJ15),"x","") | BG15: =IF(BE15="","",ROUND((BF15-BE15)/30,0)) | BM15: =SUM(BH15:BL15) -> 0 | BN15: =IF(AND(BN$6>=$BE15,BN$6<=$BF15),"x","") -> x | BO15: =IF(AND(BO$6>=$BE15,BO$6<=$BF15),"x","") -> #VALUE! | BP15: =IF(AND(BP$6>=$BE15,BP$6<=$BF15),"x","") -> #VALUE! | BQ15: =IF(AND(BQ$6>=$BE15,BQ$6<=$BF15),"x","") -> #VALUE! | BR15: =IF(AND(BR$6>=$BE15,BR$6<=$BF15),"x","") -> #VALUE! | BS15: =IF(AND(BS$6>=$BE15,BS$6<=$BF15),"x","") -> #VALUE! | BT15: =IF(AND(BT$6>=$BE15,BT$6<=$BF15),"x","") -> #VALUE! | BU15: =IF(AND(BU$6>=$BE15,BU$6<=$BF15),"x","") -> #VALUE! | ... BY15: =IF(AND(BY$6>=$BE15,BY$6<=$BF15),"x","") -> #VALUE! | CA15: =A15 -> 5 | CB15: =B15 -> Ermittl. wissenschaftlich-technischer Ressourcen und möglicher Kooperationspartner
F16: =IF(D16="","",ROUND((E16-D16)/30,0)) | U16: =SUM(G16,K16,O16) -> 0 | V16: =IF(AND(V$6>=$D16,V$6<=$E16),"x","") | W16: =IF(AND(W$6>=$D16,W$6<=$E16),"x","") | X16: =IF(AND(X$6>=$D16,X$6<=$E16),"x","") | Y16: =IF(AND(Y$6>=$D16,Y$6<=$E16),"x","") | Z16: =IF(AND(Z$6>=$D16,Z$6<=$E16),"x","") | AA16: =IF(AND(AA$6>=$D16,AA$6<=$E16),"x","") | AB16: =IF(AND(AB$6>=$D16,AB$6<=$E16),"x","") | AC16: =IF(AND(AC$6>=$D16,AC$6<=$E16),"x","") | ... AG16: =IF(AND(AG$6>=$D16,AG$6<=$E16),"x","") | AK16: =IF(AI16="","",ROUND((AJ16-AI16)/30,0)) | AQ16: =SUM(AL16:AP16) -> 0 | AR16: =IF(AND(AR$6>=$AI16,AR$6<=$AJ16),"x","") | AS16: =IF(AND(AS$6>=$AI16,AS$6<=$AJ16),"x","") | AT16: =IF(AND(AT$6>=$AI16,AT$6<=$AJ16),"x","") | AU16: =IF(AND(AU$6>=$AI16,AU$6<=$AJ16),"x","") | AV16: =IF(AND(AV$6>=$AI16,AV$6<=$AJ16),"x","") | AW16: =IF(AND(AW$6>=$AI16,AW$6<=$AJ16),"x","") | AX16: =IF(AND(AX$6>=$AI16,AX$6<=$AJ16),"x","") | AY16: =IF(AND(AY$6>=$AI16,AY$6<=$AJ16),"x","") | ... BC16: =IF(AND(BC$6>=$AI16,BC$6<=$AJ16),"x","") | BG16: =IF(BE16="","",ROUND((BF16-BE16)/30,0)) | BM16: =SUM(BH16:BL16) -> 0 | BN16: =IF(AND(BN$6>=$BE16,BN$6<=$BF16),"x","") -> x | BO16: =IF(AND(BO$6>=$BE16,BO$6<=$BF16),"x","") -> #VALUE! | BP16: =IF(AND(BP$6>=$BE16,BP$6<=$BF16),"x","") -> #VALUE! | BQ16: =IF(AND(BQ$6>=$BE16,BQ$6<=$BF16),"x","") -> #VALUE! | BR16: =IF(AND(BR$6>=$BE16,BR$6<=$BF16),"x","") -> #VALUE! | BS16: =IF(AND(BS$6>=$BE16,BS$6<=$BF16),"x","") -> #VALUE! | BT16: =IF(AND(BT$6>=$BE16,BT$6<=$BF16),"x","") -> #VALUE! | BU16: =IF(AND(BU$6>=$BE16,BU$6<=$BF16),"x","") -> #VALUE! | ... BY16: =IF(AND(BY$6>=$BE16,BY$6<=$BF16),"x","") -> #VALUE! | CA16: =A16 -> 0 | CB16: =B16 -> 0
F17: =IF(D17="","",ROUND((E17-D17)/30,0)) | U17: =SUM(G17,K17,O17) -> 0 | V17: =IF(AND(V$6>=$D17,V$6<=$E17),"x","") | W17: =IF(AND(W$6>=$D17,W$6<=$E17),"x","") | X17: =IF(AND(X$6>=$D17,X$6<=$E17),"x","") | Y17: =IF(AND(Y$6>=$D17,Y$6<=$E17),"x","") | Z17: =IF(AND(Z$6>=$D17,Z$6<=$E17),"x","") | AA17: =IF(AND(AA$6>=$D17,AA$6<=$E17),"x","") | AB17: =IF(AND(AB$6>=$D17,AB$6<=$E17),"x","") | AC17: =IF(AND(AC$6>=$D17,AC$6<=$E17),"x","") | ... AG17: =IF(AND(AG$6>=$D17,AG$6<=$E17),"x","") | AK17: =IF(AI17="","",ROUND((AJ17-AI17)/30,0)) | AQ17: =SUM(AL17:AP17) -> 0 | AR17: =IF(AND(AR$6>=$AI17,AR$6<=$AJ17),"x","") | AS17: =IF(AND(AS$6>=$AI17,AS$6<=$AJ17),"x","") | AT17: =IF(AND(AT$6>=$AI17,AT$6<=$AJ17),"x","") | AU17: =IF(AND(AU$6>=$AI17,AU$6<=$AJ17),"x","") | AV17: =IF(AND(AV$6>=$AI17,AV$6<=$AJ17),"x","") | AW17: =IF(AND(AW$6>=$AI17,AW$6<=$AJ17),"x","") | AX17: =IF(AND(AX$6>=$AI17,AX$6<=$AJ17),"x","") | AY17: =IF(AND(AY$6>=$AI17,AY$6<=$AJ17),"x","") | ... BC17: =IF(AND(BC$6>=$AI17,BC$6<=$AJ17),"x","") | BG17: =IF(BE17="","",ROUND((BF17-BE17)/30,0)) | BM17: =SUM(BH17:BL17) -> 0 | BN17: =IF(AND(BN$6>=$BE17,BN$6<=$BF17),"x","") -> x | BO17: =IF(AND(BO$6>=$BE17,BO$6<=$BF17),"x","") -> #VALUE! | BP17: =IF(AND(BP$6>=$BE17,BP$6<=$BF17),"x","") -> #VALUE! | BQ17: =IF(AND(BQ$6>=$BE17,BQ$6<=$BF17),"x","") -> #VALUE! | BR17: =IF(AND(BR$6>=$BE17,BR$6<=$BF17),"x","") -> #VALUE! | BS17: =IF(AND(BS$6>=$BE17,BS$6<=$BF17),"x","") -> #VALUE! | BT17: =IF(AND(BT$6>=$BE17,BT$6<=$BF17),"x","") -> #VALUE! | BU17: =IF(AND(BU$6>=$BE17,BU$6<=$BF17),"x","") -> #VALUE! | ... BY17: =IF(AND(BY$6>=$BE17,BY$6<=$BF17),"x","") -> #VALUE! | CA17: =A17 -> 0 | CB17: =B17 -> 0
F18: =IF(D18="","",ROUND((E18-D18)/30,0)) | U18: =SUM(G18,K18,O18) -> 0 | V18: =IF(AND(V$6>=$D18,V$6<=$E18),"x","") | W18: =IF(AND(W$6>=$D18,W$6<=$E18),"x","") | X18: =IF(AND(X$6>=$D18,X$6<=$E18),"x","") | Y18: =IF(AND(Y$6>=$D18,Y$6<=$E18),"x","") | Z18: =IF(AND(Z$6>=$D18,Z$6<=$E18),"x","") | AA18: =IF(AND(AA$6>=$D18,AA$6<=$E18),"x","") | AB18: =IF(AND(AB$6>=$D18,AB$6<=$E18),"x","") | AC18: =IF(AND(AC$6>=$D18,AC$6<=$E18),"x","") | ... AG18: =IF(AND(AG$6>=$D18,AG$6<=$E18),"x","") | AK18: =IF(AI18="","",ROUND((AJ18-AI18)/30,0)) | AQ18: =SUM(AL18:AP18) -> 0 | AR18: =IF(AND(AR$6>=$AI18,AR$6<=$AJ18),"x","") | AS18: =IF(AND(AS$6>=$AI18,AS$6<=$AJ18),"x","") | AT18: =IF(AND(AT$6>=$AI18,AT$6<=$AJ18),"x","") | AU18: =IF(AND(AU$6>=$AI18,AU$6<=$AJ18),"x","") | AV18: =IF(AND(AV$6>=$AI18,AV$6<=$AJ18),"x","") | AW18: =IF(AND(AW$6>=$AI18,AW$6<=$AJ18),"x","") | AX18: =IF(AND(AX$6>=$AI18,AX$6<=$AJ18),"x","") | AY18: =IF(AND(AY$6>=$AI18,AY$6<=$AJ18),"x","") | ... BC18: =IF(AND(BC$6>=$AI18,BC$6<=$AJ18),"x","") | BG18: =IF(BE18="","",ROUND((BF18-BE18)/30,0)) | BM18: =SUM(BH18:BL18) -> 0 | BN18: =IF(AND(BN$6>=$BE18,BN$6<=$BF18),"x","") -> x | BO18: =IF(AND(BO$6>=$BE18,BO$6<=$BF18),"x","") -> #VALUE! | BP18: =IF(AND(BP$6>=$BE18,BP$6<=$BF18),"x","") -> #VALUE! | BQ18: =IF(AND(BQ$6>=$BE18,BQ$6<=$BF18),"x","") -> #VALUE! | BR18: =IF(AND(BR$6>=$BE18,BR$6<=$BF18),"x","") -> #VALUE! | BS18: =IF(AND(BS$6>=$BE18,BS$6<=$BF18),"x","") -> #VALUE! | BT18: =IF(AND(BT$6>=$BE18,BT$6<=$BF18),"x","") -> #VALUE! | BU18: =IF(AND(BU$6>=$BE18,BU$6<=$BF18),"x","") -> #VALUE! | ... BY18: =IF(AND(BY$6>=$BE18,BY$6<=$BF18),"x","") -> #VALUE! | CA18: =A18 -> 0 | CB18: =B18 -> 0
F19: =IF(D19="","",ROUND((E19-D19)/30,0)) | U19: =SUM(G19,K19,O19) -> 0 | V19: =IF(AND(V$6>=$D19,V$6<=$E19),"x","") | W19: =IF(AND(W$6>=$D19,W$6<=$E19),"x","") | X19: =IF(AND(X$6>=$D19,X$6<=$E19),"x","") | Y19: =IF(AND(Y$6>=$D19,Y$6<=$E19),"x","") | Z19: =IF(AND(Z$6>=$D19,Z$6<=$E19),"x","") | AA19: =IF(AND(AA$6>=$D19,AA$6<=$E19),"x","") | AB19: =IF(AND(AB$6>=$D19,AB$6<=$E19),"x","") | AC19: =IF(AND(AC$6>=$D19,AC$6<=$E19),"x","") | ... AG19: =IF(AND(AG$6>=$D19,AG$6<=$E19),"x","") | AK19: =IF(AI19="","",ROUND((AJ19-AI19)/30,0)) | AQ19: =SUM(AL19:AP19) -> 0 | AR19: =IF(AND(AR$6>=$AI19,AR$6<=$AJ19),"x","") | AS19: =IF(AND(AS$6>=$AI19,AS$6<=$AJ19),"x","") | AT19: =IF(AND(AT$6>=$AI19,AT$6<=$AJ19),"x","") | AU19: =IF(AND(AU$6>=$AI19,AU$6<=$AJ19),"x","") | AV19: =IF(AND(AV$6>=$AI19,AV$6<=$AJ19),"x","") | AW19: =IF(AND(AW$6>=$AI19,AW$6<=$AJ19),"x","") | AX19: =IF(AND(AX$6>=$AI19,AX$6<=$AJ19),"x","") | AY19: =IF(AND(AY$6>=$AI19,AY$6<=$AJ19),"x","") | ... BC19: =IF(AND(BC$6>=$AI19,BC$6<=$AJ19),"x","") | BG19: =IF(BE19="","",ROUND((BF19-BE19)/30,0)) | BM19: =SUM(BH19:BL19) -> 0 | BN19: =IF(AND(BN$6>=$BE19,BN$6<=$BF19),"x","") -> x | BO19: =IF(AND(BO$6>=$BE19,BO$6<=$BF19),"x","") -> #VALUE! | BP19: =IF(AND(BP$6>=$BE19,BP$6<=$BF19),"x","") -> #VALUE! | BQ19: =IF(AND(BQ$6>=$BE19,BQ$6<=$BF19),"x","") -> #VALUE! | BR19: =IF(AND(BR$6>=$BE19,BR$6<=$BF19),"x","") -> #VALUE! | BS19: =IF(AND(BS$6>=$BE19,BS$6<=$BF19),"x","") -> #VALUE! | BT19: =IF(AND(BT$6>=$BE19,BT$6<=$BF19),"x","") -> #VALUE! | BU19: =IF(AND(BU$6>=$BE19,BU$6<=$BF19),"x","") -> #VALUE! | ... BY19: =IF(AND(BY$6>=$BE19,BY$6<=$BF19),"x","") -> #VALUE! | CA19: =A19 -> 0 | CB19: =B19 -> 0
F20: =IF(D20="","",ROUND((E20-D20)/30,0)) | U20: =SUM(G20,K20,O20) -> 0 | V20: =IF(AND(V$6>=$D20,V$6<=$E20),"x","") | W20: =IF(AND(W$6>=$D20,W$6<=$E20),"x","") | X20: =IF(AND(X$6>=$D20,X$6<=$E20),"x","") | Y20: =IF(AND(Y$6>=$D20,Y$6<=$E20),"x","") | Z20: =IF(AND(Z$6>=$D20,Z$6<=$E20),"x","") | AA20: =IF(AND(AA$6>=$D20,AA$6<=$E20),"x","") | AB20: =IF(AND(AB$6>=$D20,AB$6<=$E20),"x","") | AC20: =IF(AND(AC$6>=$D20,AC$6<=$E20),"x","") | ... AG20: =IF(AND(AG$6>=$D20,AG$6<=$E20),"x","") | AK20: =IF(AI20="","",ROUND((AJ20-AI20)/30,0)) | AQ20: =SUM(AL20:AP20) -> 0 | AR20: =IF(AND(AR$6>=$AI20,AR$6<=$AJ20),"x","") | AS20: =IF(AND(AS$6>=$AI20,AS$6<=$AJ20),"x","") | AT20: =IF(AND(AT$6>=$AI20,AT$6<=$AJ20),"x","") | AU20: =IF(AND(AU$6>=$AI20,AU$6<=$AJ20),"x","") | AV20: =IF(AND(AV$6>=$AI20,AV$6<=$AJ20),"x","") | AW20: =IF(AND(AW$6>=$AI20,AW$6<=$AJ20),"x","") | AX20: =IF(AND(AX$6>=$AI20,AX$6<=$AJ20),"x","") | AY20: =IF(AND(AY$6>=$AI20,AY$6<=$AJ20),"x","") | ... BC20: =IF(AND(BC$6>=$AI20,BC$6<=$AJ20),"x","") | BG20: =IF(BE20="","",ROUND((BF20-BE20)/30,0)) | BM20: =SUM(BH20:BL20) -> 0 | BN20: =IF(AND(BN$6>=$BE20,BN$6<=$BF20),"x","") -> x | BO20: =IF(AND(BO$6>=$BE20,BO$6<=$BF20),"x","") -> #VALUE! | BP20: =IF(AND(BP$6>=$BE20,BP$6<=$BF20),"x","") -> #VALUE! | BQ20: =IF(AND(BQ$6>=$BE20,BQ$6<=$BF20),"x","") -> #VALUE! | BR20: =IF(AND(BR$6>=$BE20,BR$6<=$BF20),"x","") -> #VALUE! | BS20: =IF(AND(BS$6>=$BE20,BS$6<=$BF20),"x","") -> #VALUE! | BT20: =IF(AND(BT$6>=$BE20,BT$6<=$BF20),"x","") -> #VALUE! | BU20: =IF(AND(BU$6>=$BE20,BU$6<=$BF20),"x","") -> #VALUE! | ... BY20: =IF(AND(BY$6>=$BE20,BY$6<=$BF20),"x","") -> #VALUE! | CA20: =A20 -> 0 | CB20: =B20 -> 0
F21: =IF(D21="","",ROUND((E21-D21)/30,0)) | U21: =SUM(G21,K21,O21) -> 0 | V21: =IF(AND(V$6>=$D21,V$6<=$E21),"x","") | W21: =IF(AND(W$6>=$D21,W$6<=$E21),"x","") | X21: =IF(AND(X$6>=$D21,X$6<=$E21),"x","") | Y21: =IF(AND(Y$6>=$D21,Y$6<=$E21),"x","") | Z21: =IF(AND(Z$6>=$D21,Z$6<=$E21),"x","") | AA21: =IF(AND(AA$6>=$D21,AA$6<=$E21),"x","") | AB21: =IF(AND(AB$6>=$D21,AB$6<=$E21),"x","") | AC21: =IF(AND(AC$6>=$D21,AC$6<=$E21),"x","") | ... AG21: =IF(AND(AG$6>=$D21,AG$6<=$E21),"x","") | AK21: =IF(AI21="","",ROUND((AJ21-AI21)/30,0)) | AQ21: =SUM(AL21:AP21) -> 0 | AR21: =IF(AND(AR$6>=$AI21,AR$6<=$AJ21),"x","") | AS21: =IF(AND(AS$6>=$AI21,AS$6<=$AJ21),"x","") | AT21: =IF(AND(AT$6>=$AI21,AT$6<=$AJ21),"x","") | AU21: =IF(AND(AU$6>=$AI21,AU$6<=$AJ21),"x","") | AV21: =IF(AND(AV$6>=$AI21,AV$6<=$AJ21),"x","") | AW21: =IF(AND(AW$6>=$AI21,AW$6<=$AJ21),"x","") | AX21: =IF(AND(AX$6>=$AI21,AX$6<=$AJ21),"x","") | AY21: =IF(AND(AY$6>=$AI21,AY$6<=$AJ21),"x","") | ... BC21: =IF(AND(BC$6>=$AI21,BC$6<=$AJ21),"x","") | BG21: =IF(BE21="","",ROUND((BF21-BE21)/30,0)) | BM21: =SUM(BH21:BL21) -> 0 | BN21: =IF(AND(BN$6>=$BE21,BN$6<=$BF21),"x","") -> x | BO21: =IF(AND(BO$6>=$BE21,BO$6<=$BF21),"x","") -> #VALUE! | BP21: =IF(AND(BP$6>=$BE21,BP$6<=$BF21),"x","") -> #VALUE! | BQ21: =IF(AND(BQ$6>=$BE21,BQ$6<=$BF21),"x","") -> #VALUE! | BR21: =IF(AND(BR$6>=$BE21,BR$6<=$BF21),"x","") -> #VALUE! | BS21: =IF(AND(BS$6>=$BE21,BS$6<=$BF21),"x","") -> #VALUE! | BT21: =IF(AND(BT$6>=$BE21,BT$6<=$BF21),"x","") -> #VALUE! | BU21: =IF(AND(BU$6>=$BE21,BU$6<=$BF21),"x","") -> #VALUE! | ... BY21: =IF(AND(BY$6>=$BE21,BY$6<=$BF21),"x","") -> #VALUE! | CA21: =A21 -> 0 | CB21: =B21 -> 0
F22: =IF(D22="","",ROUND((E22-D22)/30,0)) | U22: =SUM(G22,K22,O22) -> 0 | V22: =IF(AND(V$6>=$D22,V$6<=$E22),"x","") | W22: =IF(AND(W$6>=$D22,W$6<=$E22),"x","") | X22: =IF(AND(X$6>=$D22,X$6<=$E22),"x","") | Y22: =IF(AND(Y$6>=$D22,Y$6<=$E22),"x","") | Z22: =IF(AND(Z$6>=$D22,Z$6<=$E22),"x","") | AA22: =IF(AND(AA$6>=$D22,AA$6<=$E22),"x","") | AB22: =IF(AND(AB$6>=$D22,AB$6<=$E22),"x","") | AC22: =IF(AND(AC$6>=$D22,AC$6<=$E22),"x","") | ... AG22: =IF(AND(AG$6>=$D22,AG$6<=$E22),"x","") | AK22: =IF(AI22="","",ROUND((AJ22-AI22)/30,0)) | AQ22: =SUM(AL22:AP22) -> 0 | AR22: =IF(AND(AR$6>=$AI22,AR$6<=$AJ22),"x","") | AS22: =IF(AND(AS$6>=$AI22,AS$6<=$AJ22),"x","") | AT22: =IF(AND(AT$6>=$AI22,AT$6<=$AJ22),"x","") | AU22: =IF(AND(AU$6>=$AI22,AU$6<=$AJ22),"x","") | AV22: =IF(AND(AV$6>=$AI22,AV$6<=$AJ22),"x","") | AW22: =IF(AND(AW$6>=$AI22,AW$6<=$AJ22),"x","") | AX22: =IF(AND(AX$6>=$AI22,AX$6<=$AJ22),"x","") | AY22: =IF(AND(AY$6>=$AI22,AY$6<=$AJ22),"x","") | ... BC22: =IF(AND(BC$6>=$AI22,BC$6<=$AJ22),"x","") | BG22: =IF(BE22="","",ROUND((BF22-BE22)/30,0)) | BM22: =SUM(BH22:BL22) -> 0 | BN22: =IF(AND(BN$6>=$BE22,BN$6<=$BF22),"x","") -> x | BO22: =IF(AND(BO$6>=$BE22,BO$6<=$BF22),"x","") -> #VALUE! | BP22: =IF(AND(BP$6>=$BE22,BP$6<=$BF22),"x","") -> #VALUE! | BQ22: =IF(AND(BQ$6>=$BE22,BQ$6<=$BF22),"x","") -> #VALUE! | BR22: =IF(AND(BR$6>=$BE22,BR$6<=$BF22),"x","") -> #VALUE! | BS22: =IF(AND(BS$6>=$BE22,BS$6<=$BF22),"x","") -> #VALUE! | BT22: =IF(AND(BT$6>=$BE22,BT$6<=$BF22),"x","") -> #VALUE! | BU22: =IF(AND(BU$6>=$BE22,BU$6<=$BF22),"x","") -> #VALUE! | ... BY22: =IF(AND(BY$6>=$BE22,BY$6<=$BF22),"x","") -> #VALUE! | CA22: =A22 -> 0 | CB22: =B22 -> 0
F23: =IF(D23="","",ROUND((E23-D23)/30,0)) | U23: =SUM(G23,K23,O23) -> 0 | V23: =IF(AND(V$6>=$D23,V$6<=$E23),"x","") | W23: =IF(AND(W$6>=$D23,W$6<=$E23),"x","") | X23: =IF(AND(X$6>=$D23,X$6<=$E23),"x","") | Y23: =IF(AND(Y$6>=$D23,Y$6<=$E23),"x","") | Z23: =IF(AND(Z$6>=$D23,Z$6<=$E23),"x","") | AA23: =IF(AND(AA$6>=$D23,AA$6<=$E23),"x","") | AB23: =IF(AND(AB$6>=$D23,AB$6<=$E23),"x","") | AC23: =IF(AND(AC$6>=$D23,AC$6<=$E23),"x","") | ... AG23: =IF(AND(AG$6>=$D23,AG$6<=$E23),"x","") | AK23: =IF(AI23="","",ROUND((AJ23-AI23)/30,0)) | AQ23: =SUM(AL23:AP23) -> 0 | AR23: =IF(AND(AR$6>=$AI23,AR$6<=$AJ23),"x","") | AS23: =IF(AND(AS$6>=$AI23,AS$6<=$AJ23),"x","") | AT23: =IF(AND(AT$6>=$AI23,AT$6<=$AJ23),"x","") | AU23: =IF(AND(AU$6>=$AI23,AU$6<=$AJ23),"x","") | AV23: =IF(AND(AV$6>=$AI23,AV$6<=$AJ23),"x","") | AW23: =IF(AND(AW$6>=$AI23,AW$6<=$AJ23),"x","") | AX23: =IF(AND(AX$6>=$AI23,AX$6<=$AJ23),"x","") | AY23: =IF(AND(AY$6>=$AI23,AY$6<=$AJ23),"x","") | ... BC23: =IF(AND(BC$6>=$AI23,BC$6<=$AJ23),"x","") | BG23: =IF(BE23="","",ROUND((BF23-BE23)/30,0)) | BM23: =SUM(BH23:BL23) -> 0 | BN23: =IF(AND(BN$6>=$BE23,BN$6<=$BF23),"x","") -> x | BO23: =IF(AND(BO$6>=$BE23,BO$6<=$BF23),"x","") -> #VALUE! | BP23: =IF(AND(BP$6>=$BE23,BP$6<=$BF23),"x","") -> #VALUE! | BQ23: =IF(AND(BQ$6>=$BE23,BQ$6<=$BF23),"x","") -> #VALUE! | BR23: =IF(AND(BR$6>=$BE23,BR$6<=$BF23),"x","") -> #VALUE! | BS23: =IF(AND(BS$6>=$BE23,BS$6<=$BF23),"x","") -> #VALUE! | BT23: =IF(AND(BT$6>=$BE23,BT$6<=$BF23),"x","") -> #VALUE! | BU23: =IF(AND(BU$6>=$BE23,BU$6<=$BF23),"x","") -> #VALUE! | ... BY23: =IF(AND(BY$6>=$BE23,BY$6<=$BF23),"x","") -> #VALUE! | CA23: =A23 -> 0 | CB23: =B23 -> 0
F24: =IF(D24="","",ROUND((E24-D24)/30,0)) | U24: =SUM(G24,K24,O24) -> 0 | V24: =IF(AND(V$6>=$D24,V$6<=$E24),"x","") | W24: =IF(AND(W$6>=$D24,W$6<=$E24),"x","") | X24: =IF(AND(X$6>=$D24,X$6<=$E24),"x","") | Y24: =IF(AND(Y$6>=$D24,Y$6<=$E24),"x","") | Z24: =IF(AND(Z$6>=$D24,Z$6<=$E24),"x","") | AA24: =IF(AND(AA$6>=$D24,AA$6<=$E24),"x","") | AB24: =IF(AND(AB$6>=$D24,AB$6<=$E24),"x","") | AC24: =IF(AND(AC$6>=$D24,AC$6<=$E24),"x","") | ... AG24: =IF(AND(AG$6>=$D24,AG$6<=$E24),"x","") | AK24: =IF(AI24="","",ROUND((AJ24-AI24)/30,0)) | AQ24: =SUM(AL24:AP24) -> 0 | AR24: =IF(AND(AR$6>=$AI24,AR$6<=$AJ24),"x","") | AS24: =IF(AND(AS$6>=$AI24,AS$6<=$AJ24),"x","") | AT24: =IF(AND(AT$6>=$AI24,AT$6<=$AJ24),"x","") | AU24: =IF(AND(AU$6>=$AI24,AU$6<=$AJ24),"x","") | AV24: =IF(AND(AV$6>=$AI24,AV$6<=$AJ24),"x","") | AW24: =IF(AND(AW$6>=$AI24,AW$6<=$AJ24),"x","") | AX24: =IF(AND(AX$6>=$AI24,AX$6<=$AJ24),"x","") | AY24: =IF(AND(AY$6>=$AI24,AY$6<=$AJ24),"x","") | ... BC24: =IF(AND(BC$6>=$AI24,BC$6<=$AJ24),"x","") | BG24: =IF(BE24="","",ROUND((BF24-BE24)/30,0)) | BM24: =SUM(BH24:BL24) -> 0 | BN24: =IF(AND(BN$6>=$BE24,BN$6<=$BF24),"x","") -> x | BO24: =IF(AND(BO$6>=$BE24,BO$6<=$BF24),"x","") -> #VALUE! | BP24: =IF(AND(BP$6>=$BE24,BP$6<=$BF24),"x","") -> #VALUE! | BQ24: =IF(AND(BQ$6>=$BE24,BQ$6<=$BF24),"x","") -> #VALUE! | BR24: =IF(AND(BR$6>=$BE24,BR$6<=$BF24),"x","") -> #VALUE! | BS24: =IF(AND(BS$6>=$BE24,BS$6<=$BF24),"x","") -> #VALUE! | BT24: =IF(AND(BT$6>=$BE24,BT$6<=$BF24),"x","") -> #VALUE! | BU24: =IF(AND(BU$6>=$BE24,BU$6<=$BF24),"x","") -> #VALUE! | ... BY24: =IF(AND(BY$6>=$BE24,BY$6<=$BF24),"x","") -> #VALUE! | CA24: =A24 -> 0 | CB24: =B24 -> 0
F25: =IF(D25="","",ROUND((E25-D25)/30,0)) | U25: =SUM(G25,K25,O25) -> 0 | V25: =IF(AND(V$6>=$D25,V$6<=$E25),"x","") | W25: =IF(AND(W$6>=$D25,W$6<=$E25),"x","") | X25: =IF(AND(X$6>=$D25,X$6<=$E25),"x","") | Y25: =IF(AND(Y$6>=$D25,Y$6<=$E25),"x","") | Z25: =IF(AND(Z$6>=$D25,Z$6<=$E25),"x","") | AA25: =IF(AND(AA$6>=$D25,AA$6<=$E25),"x","") | AB25: =IF(AND(AB$6>=$D25,AB$6<=$E25),"x","") | AC25: =IF(AND(AC$6>=$D25,AC$6<=$E25),"x","") | ... AG25: =IF(AND(AG$6>=$D25,AG$6<=$E25),"x","") | AK25: =IF(AI25="","",ROUND((AJ25-AI25)/30,0)) | AQ25: =SUM(AL25:AP25) -> 0 | AR25: =IF(AND(AR$6>=$AI25,AR$6<=$AJ25),"x","") | AS25: =IF(AND(AS$6>=$AI25,AS$6<=$AJ25),"x","") | AT25: =IF(AND(AT$6>=$AI25,AT$6<=$AJ25),"x","") | AU25: =IF(AND(AU$6>=$AI25,AU$6<=$AJ25),"x","") | AV25: =IF(AND(AV$6>=$AI25,AV$6<=$AJ25),"x","") | AW25: =IF(AND(AW$6>=$AI25,AW$6<=$AJ25),"x","") | AX25: =IF(AND(AX$6>=$AI25,AX$6<=$AJ25),"x","") | AY25: =IF(AND(AY$6>=$AI25,AY$6<=$AJ25),"x","") | ... BC25: =IF(AND(BC$6>=$AI25,BC$6<=$AJ25),"x","") | BG25: =IF(BE25="","",ROUND((BF25-BE25)/30,0)) | BM25: =SUM(BH25:BL25) -> 0 | BN25: =IF(AND(BN$6>=$BE25,BN$6<=$BF25),"x","") -> x | BO25: =IF(AND(BO$6>=$BE25,BO$6<=$BF25),"x","") -> #VALUE! | BP25: =IF(AND(BP$6>=$BE25,BP$6<=$BF25),"x","") -> #VALUE! | BQ25: =IF(AND(BQ$6>=$BE25,BQ$6<=$BF25),"x","") -> #VALUE! | BR25: =IF(AND(BR$6>=$BE25,BR$6<=$BF25),"x","") -> #VALUE! | BS25: =IF(AND(BS$6>=$BE25,BS$6<=$BF25),"x","") -> #VALUE! | BT25: =IF(AND(BT$6>=$BE25,BT$6<=$BF25),"x","") -> #VALUE! | BU25: =IF(AND(BU$6>=$BE25,BU$6<=$BF25),"x","") -> #VALUE! | ... BY25: =IF(AND(BY$6>=$BE25,BY$6<=$BF25),"x","") -> #VALUE! | CA25: =A25 -> 0 | CB25: =B25 -> 0
F26: =IF(D26="","",ROUND((E26-D26)/30,0)) | U26: =SUM(G26,K26,O26) -> 0 | V26: =IF(AND(V$6>=$D26,V$6<=$E26),"x","") | W26: =IF(AND(W$6>=$D26,W$6<=$E26),"x","") | X26: =IF(AND(X$6>=$D26,X$6<=$E26),"x","") | Y26: =IF(AND(Y$6>=$D26,Y$6<=$E26),"x","") | Z26: =IF(AND(Z$6>=$D26,Z$6<=$E26),"x","") | AA26: =IF(AND(AA$6>=$D26,AA$6<=$E26),"x","") | AB26: =IF(AND(AB$6>=$D26,AB$6<=$E26),"x","") | AC26: =IF(AND(AC$6>=$D26,AC$6<=$E26),"x","") | ... AG26: =IF(AND(AG$6>=$D26,AG$6<=$E26),"x","") | AK26: =IF(AI26="","",ROUND((AJ26-AI26)/30,0)) | AQ26: =SUM(AL26:AP26) -> 0 | AR26: =IF(AND(AR$6>=$AI26,AR$6<=$AJ26),"x","") | AS26: =IF(AND(AS$6>=$AI26,AS$6<=$AJ26),"x","") | AT26: =IF(AND(AT$6>=$AI26,AT$6<=$AJ26),"x","") | AU26: =IF(AND(AU$6>=$AI26,AU$6<=$AJ26),"x","") | AV26: =IF(AND(AV$6>=$AI26,AV$6<=$AJ26),"x","") | AW26: =IF(AND(AW$6>=$AI26,AW$6<=$AJ26),"x","") | AX26: =IF(AND(AX$6>=$AI26,AX$6<=$AJ26),"x","") | AY26: =IF(AND(AY$6>=$AI26,AY$6<=$AJ26),"x","") | ... BC26: =IF(AND(BC$6>=$AI26,BC$6<=$AJ26),"x","") | BG26: =IF(BE26="","",ROUND((BF26-BE26)/30,0)) | BM26: =SUM(BH26:BL26) -> 0 | BN26: =IF(AND(BN$6>=$BE26,BN$6<=$BF26),"x","") -> x | BO26: =IF(AND(BO$6>=$BE26,BO$6<=$BF26),"x","") -> #VALUE! | BP26: =IF(AND(BP$6>=$BE26,BP$6<=$BF26),"x","") -> #VALUE! | BQ26: =IF(AND(BQ$6>=$BE26,BQ$6<=$BF26),"x","") -> #VALUE! | BR26: =IF(AND(BR$6>=$BE26,BR$6<=$BF26),"x","") -> #VALUE! | BS26: =IF(AND(BS$6>=$BE26,BS$6<=$BF26),"x","") -> #VALUE! | BT26: =IF(AND(BT$6>=$BE26,BT$6<=$BF26),"x","") -> #VALUE! | BU26: =IF(AND(BU$6>=$BE26,BU$6<=$BF26),"x","") -> #VALUE! | ... BY26: =IF(AND(BY$6>=$BE26,BY$6<=$BF26),"x","") -> #VALUE! | CA26: =A26 -> 0 | CB26: =B26 -> 0
F27: =IF(D27="","",ROUND((E27-D27)/30,0)) | U27: =SUM(G27,K27,O27) -> 0 | V27: =IF(AND(V$6>=$D27,V$6<=$E27),"x","") | W27: =IF(AND(W$6>=$D27,W$6<=$E27),"x","") | X27: =IF(AND(X$6>=$D27,X$6<=$E27),"x","") | Y27: =IF(AND(Y$6>=$D27,Y$6<=$E27),"x","") | Z27: =IF(AND(Z$6>=$D27,Z$6<=$E27),"x","") | AA27: =IF(AND(AA$6>=$D27,AA$6<=$E27),"x","") | AB27: =IF(AND(AB$6>=$D27,AB$6<=$E27),"x","") | AC27: =IF(AND(AC$6>=$D27,AC$6<=$E27),"x","") | ... AG27: =IF(AND(AG$6>=$D27,AG$6<=$E27),"x","") | AK27: =IF(AI27="","",ROUND((AJ27-AI27)/30,0)) | AQ27: =SUM(AL27:AP27) -> 0 | AR27: =IF(AND(AR$6>=$AI27,AR$6<=$AJ27),"x","") | AS27: =IF(AND(AS$6>=$AI27,AS$6<=$AJ27),"x","") | AT27: =IF(AND(AT$6>=$AI27,AT$6<=$AJ27),"x","") | AU27: =IF(AND(AU$6>=$AI27,AU$6<=$AJ27),"x","") | AV27: =IF(AND(AV$6>=$AI27,AV$6<=$AJ27),"x","") | AW27: =IF(AND(AW$6>=$AI27,AW$6<=$AJ27),"x","") | AX27: =IF(AND(AX$6>=$AI27,AX$6<=$AJ27),"x","") | AY27: =IF(AND(AY$6>=$AI27,AY$6<=$AJ27),"x","") | ... BC27: =IF(AND(BC$6>=$AI27,BC$6<=$AJ27),"x","") | BG27: =IF(BE27="","",ROUND((BF27-BE27)/30,0)) | BM27: =SUM(BH27:BL27) -> 0 | BN27: =IF(AND(BN$6>=$BE27,BN$6<=$BF27),"x","") -> x | BO27: =IF(AND(BO$6>=$BE27,BO$6<=$BF27),"x","") -> #VALUE! | BP27: =IF(AND(BP$6>=$BE27,BP$6<=$BF27),"x","") -> #VALUE! | BQ27: =IF(AND(BQ$6>=$BE27,BQ$6<=$BF27),"x","") -> #VALUE! | BR27: =IF(AND(BR$6>=$BE27,BR$6<=$BF27),"x","") -> #VALUE! | BS27: =IF(AND(BS$6>=$BE27,BS$6<=$BF27),"x","") -> #VALUE! | BT27: =IF(AND(BT$6>=$BE27,BT$6<=$BF27),"x","") -> #VALUE! | BU27: =IF(AND(BU$6>=$BE27,BU$6<=$BF27),"x","") -> #VALUE! | ... BY27: =IF(AND(BY$6>=$BE27,BY$6<=$BF27),"x","") -> #VALUE! | CA27: =A27 -> 0 | CB27: =B27 -> 0
... F36: =IF(D36="","",ROUND((E36-D36)/30,0)) | U36: =SUM(G36,K36,O36) -> 0 | V36: =IF(AND(V$6>=$D36,V$6<=$E36),"x","") | W36: =IF(AND(W$6>=$D36,W$6<=$E36),"x","") | X36: =IF(AND(X$6>=$D36,X$6<=$E36),"x","") | Y36: =IF(AND(Y$6>=$D36,Y$6<=$E36),"x","") | Z36: =IF(AND(Z$6>=$D36,Z$6<=$E36),"x","") | AA36: =IF(AND(AA$6>=$D36,AA$6<=$E36),"x","") | AB36: =IF(AND(AB$6>=$D36,AB$6<=$E36),"x","") | AC36: =IF(AND(AC$6>=$D36,AC$6<=$E36),"x","") | ... AG36: =IF(AND(AG$6>=$D36,AG$6<=$E36),"x","") | AK36: =IF(AI36="","",ROUND((AJ36-AI36)/30,0)) | AQ36: =SUM(AL36:AP36) -> 0 | AR36: =IF(AND(AR$6>=$AI36,AR$6<=$AJ36),"x","") | AS36: =IF(AND(AS$6>=$AI36,AS$6<=$AJ36),"x","") | AT36: =IF(AND(AT$6>=$AI36,AT$6<=$AJ36),"x","") | AU36: =IF(AND(AU$6>=$AI36,AU$6<=$AJ36),"x","") | AV36: =IF(AND(AV$6>=$AI36,AV$6<=$AJ36),"x","") | AW36: =IF(AND(AW$6>=$AI36,AW$6<=$AJ36),"x","") | AX36: =IF(AND(AX$6>=$AI36,AX$6<=$AJ36),"x","") | AY36: =IF(AND(AY$6>=$AI36,AY$6<=$AJ36),"x","") | ... BC36: =IF(AND(BC$6>=$AI36,BC$6<=$AJ36),"x","") | BG36: =IF(BE36="","",ROUND((BF36-BE36)/30,0)) | BM36: =SUM(BH36:BL36) -> 0 | BN36: =IF(AND(BN$6>=$BE36,BN$6<=$BF36),"x","") -> x | BO36: =IF(AND(BO$6>=$BE36,BO$6<=$BF36),"x","") -> #VALUE! | BP36: =IF(AND(BP$6>=$BE36,BP$6<=$BF36),"x","") -> #VALUE! | BQ36: =IF(AND(BQ$6>=$BE36,BQ$6<=$BF36),"x","") -> #VALUE! | BR36: =IF(AND(BR$6>=$BE36,BR$6<=$BF36),"x","") -> #VALUE! | BS36: =IF(AND(BS$6>=$BE36,BS$6<=$BF36),"x","") -> #VALUE! | BT36: =IF(AND(BT$6>=$BE36,BT$6<=$BF36),"x","") -> #VALUE! | BU36: =IF(AND(BU$6>=$BE36,BU$6<=$BF36),"x","") -> #VALUE! | ... BY36: =IF(AND(BY$6>=$BE36,BY$6<=$BF36),"x","") -> #VALUE! | CA36: =A36 -> 0 | CB36: =B36 -> 0
F37: Summe PM | G37: =SUM(G8:G36) -> 4 | K37: =SUM(K8:K36) -> 1.5 | O37: =SUM(O8:O36) -> 2.5 | S37: =SUM(S8:S36) -> 0 | T37: =SUM(T8:T36) -> 0 | U37: =SUM(U8:U36) -> 8 | V37: =SUM(V39:AG39) -> 0 | AK37: PM | AL37: =SUM(AL8:AL36) -> 0 | AM37: =SUM(AM8:AM36) -> 0 | AN37: =SUM(AN8:AN36) -> 0 | AO37: =SUM(AO8:AO36) -> 0 | AP37: =SUM(AP8:AP36) -> 0 | AQ37: =SUM(AQ8:AQ36) -> 0 | AR37: =SUM(AR39:BC39) -> 0 | BG37: PM | BH37: =SUM(BH8:BH36) -> 0 | BI37: =SUM(BI8:BI36) -> 0 | BJ37: =SUM(BJ8:BJ36) -> 0 | BK37: =SUM(BK8:BK36) -> 0 | BL37: =SUM(BL8:BL36) -> 0 | BM37: =SUM(BM8:BM36) -> 0 | BN37: =SUM(BN39:BY39) -> #VALUE!
F38: Summe h | H38: =SUM(H8:H36) -> 693.33333 | I38: =SUM(I8:I36) -> 645.336 | J38: =SUM(J8:J36) -> 47.997333 | L38: =SUM(L8:L36) -> 260 | M38: =SUM(M8:M36) -> 552.17 | N38: =SUM(N8:N36) -> -292.17 | P38: =SUM(P8:P36) -> 216.66667 | Q38: =SUM(Q8:Q36) -> 360 | R38: =SUM(R8:R36) -> -143.33333
F39: € | G39: =G37*G7 -> 40000 | H39: =H38*'Planung Personal'!$W$9 -> 39998.4 | I39: =I38*'Planung Personal'!$W$9 -> 37229.434 | J39: =J38*'Planung Personal'!$W$9 -> 2768.9662 | K39: =K37*K7 -> 4837.5 | L39: =L38*'Planung Personal'!$W$11 -> 4838.6 | M39: =M38*'Planung Personal'!$W$11 -> 10275.884 | N39: =N38*'Planung Personal'!$W$11 -> -5437.2837 | O39: =O37*O7 -> 7437.5 | P39: =P38*'Planung Personal'!$W$13 -> 7438.1667 | Q39: =Q38*'Planung Personal'!$W$13 -> 12358.8 | R39: =R38*'Planung Personal'!$W$13 -> -4920.6333 | S39: =S37*S7 -> 0 | T39: =T37*T7 -> 0 | V39: =SUM(V9:V12,V14:V17,V19:V24,V26:V30,V32:V36) -> 0 | W39: =SUM(W9:W12,W14:W17,W19:W24,W26:W30,W32:W36) -> 0 | X39: =SUM(X9:X12,X14:X17,X19:X24,X26:X30,X32:X36) -> 0 | Y39: =SUM(Y9:Y12,Y14:Y17,Y19:Y24,Y26:Y30,Y32:Y36) -> 0 | Z39: =SUM(Z9:Z12,Z14:Z17,Z19:Z24,Z26:Z30,Z32:Z36) -> 0 | AA39: =SUM(AA9:AA12,AA14:AA17,AA19:AA24,AA26:AA30,AA32:AA36) -> 0 | AB39: =SUM(AB9:AB12,AB14:AB17,AB19:AB24,AB26:AB30,AB32:AB36) -> 0 | AC39: =SUM(AC9:AC12,AC14:AC17,AC19:AC24,AC26:AC30,AC32:AC36) -> 0 | ... AG39: =SUM(AG9:AG12,AG14:AG17,AG19:AG24,AG26:AG30,AG32:AG36) -> 0 | AK39: € | AL39: =AL37*AL7 -> 0 | AM39: =AM37*AM7 -> 0 | AN39: =AN37*AN7 -> 0 | AO39: =AO37*AO7 -> 0 | AP39: =AP37*AP7 -> 0 | AR39: =SUM(AR9:AR12,AR14:AR17,AR19:AR24,AR26:AR30,AR32:AR36) -> 0 | AS39: =SUM(AS9:AS12,AS14:AS17,AS19:AS24,AS26:AS30,AS32:AS36) -> 0 | AT39: =SUM(AT9:AT12,AT14:AT17,AT19:AT24,AT26:AT30,AT32:AT36) -> 0 | AU39: =SUM(AU9:AU12,AU14:AU17,AU19:AU24,AU26:AU30,AU32:AU36) -> 0 | AV39: =SUM(AV9:AV12,AV14:AV17,AV19:AV24,AV26:AV30,AV32:AV36) -> 0 | AW39: =SUM(AW9:AW12,AW14:AW17,AW19:AW24,AW26:AW30,AW32:AW36) -> 0 | AX39: =SUM(AX9:AX12,AX14:AX17,AX19:AX24,AX26:AX30,AX32:AX36) -> 0 | AY39: =SUM(AY9:AY12,AY14:AY17,AY19:AY24,AY26:AY30,AY32:AY36) -> 0 | ... BC39: =SUM(BC9:BC12,BC14:BC17,BC19:BC24,BC26:BC30,BC32:BC36) -> 0 | BG39: € | BH39: =BH37*BH7 -> 0 | BI39: =BI37*BI7 -> 0 | BJ39: =BJ37*BJ7 -> 0 | BK39: =BK37*BK7 -> 0 | BL39: =BL37*BL7 -> 0 | BN39: =SUM(BN9:BN12,BN14:BN17,BN19:BN24,BN26:BN30,BN32:BN36) -> 0 | BO39: =SUM(BO9:BO12,BO14:BO17,BO19:BO24,BO26:BO30,BO32:BO36) -> #VALUE! | BP39: =SUM(BP9:BP12,BP14:BP17,BP19:BP24,BP26:BP30,BP32:BP36) -> #VALUE! | BQ39: =SUM(BQ9:BQ12,BQ14:BQ17,BQ19:BQ24,BQ26:BQ30,BQ32:BQ36) -> #VALUE! | BR39: =SUM(BR9:BR12,BR14:BR17,BR19:BR24,BR26:BR30,BR32:BR36) -> #VALUE! | BS39: =SUM(BS9:BS12,BS14:BS17,BS19:BS24,BS26:BS30,BS32:BS36) -> #VALUE! | BT39: =SUM(BT9:BT12,BT14:BT17,BT19:BT24,BT26:BT30,BT32:BT36) -> #VALUE! | BU39: =SUM(BU9:BU12,BU14:BU17,BU19:BU24,BU26:BU30,BU32:BU36) -> #VALUE! | ... BY39: =SUM(BY9:BY12,BY14:BY17,BY19:BY24,BY26:BY30,BY32:BY36) -> #VALUE!
F40: ZA gesamt | G40: =SUM(I39,M39,Q39) -> 59864.118 | V40: =SUM(V39:AG39) -> 0 | AK40: € gesamt | AL40: =SUM(AL39:AP39) -> 0 | AR40: =SUM(AR39:BC39) -> 0 | BG40: € gesamt | BH40: =SUM(BH39:BL39) -> 0 | BN40: =SUM(BN39:BY39) -> #VALUE!
F42: PM max | G42: 0 | K42: 0 | R42: T | U42: =SUMIF($C$8:$U$36,"x",$U$8:$U$36) -> 6 | AK42: PM max | AL42: 0 | AM42: 0 | BG42: PM max | BH42: 0 | BI42: 0
R43: NT | U43: =U37-U42 -> 2
A45: 1 | B45: 2 | C45: 3 | D45: 4 | E45: 5 | F45: 6 | G45: 7 | H45: 8 | I45: 9 | J45: 10 | K45: 11 | L45: 12 | M45: 13 | N45: 14 | O45: 15 | P45: 16 | Q45: 17 | R45: 18 | S45: 19 | T45: 20 | U45: 21 | V45: 22 | W45: 23 | X45: 24 | Y45: 25 | Z45: 26 | AA45: 27 | AB45: 28 | AC45: 29 | AD45: 30 | AE45: 31 | AF45: 32 | AG45: 33 | AH45: 34 | AI45: 35 | AJ45: 36 | AK45: 37 | AL45: 38 | AM45: 39 | AN45: 40 | AO45: 41 | AP45: 42 | AQ45: 43 | AR45: 44 | AS45: 45 | AT45: 46 | AU45: 47 | AV45: 48 | AW45: 49 | AX45: 50 | AY45: 51 | AZ45: 52 | BA45: 53 | BB45: 54 | BC45: 55 | BD45: 56 | BE45: 57 | BF45: 58 | BG45: 59 | BH45: 60 | BI45: 61 | BJ45: 62 | BK45: 63 | BL45: 64 | BM45: 65 | BN45: 66 | BO45: 67 | BP45: 68 | BQ45: 69 | BR45: 70 | BS45: 71 | BT45: 72 | BU45: 73 | BV45: 74 | BW45: 75 | BX45: 76 | BY45: 77 | BZ45: 78 | CA45: 79
G50: =G37*173.33 -> 693.32 | K50: =K37*173.33 -> 259.995 | O50: =2.5*173.33/2 -> 216.6625 | Q50: =SUM(G50:O50) -> 1169.9775
D83: 1 | E83: 2 | F83: 3 | G83: 4 | K83: 5 | O83: 6 | S83: 6 | T83: 6 | U83: 7 | V83: 8 | W83: 9 | X83: 10 | Y83: 11 | Z83: 12 | AA83: 13 | AB83: 14 | AC83: 15 | AD83: 16 | AE83: 17 | AF83: 18 | AG83: 19 | AH83: 20 | AI83: 21 | AJ83: 22 | AK83: 23 | AL83: 24 | AM83: 25 | AN83: 26 | AO83: 6 | AP83: 6 | AQ83: 27 | AR83: 28 | AS83: 29 | AT83: 30 | AU83: 31 | AV83: 32 | AW83: 33 | AX83: 34 | AY83: 35 | AZ83: 36 | BA83: 37 | BB83: 38 | BC83: 39 | BD83: 40 | BE83: 41 | BF83: 42 | BG83: 43 | BH83: 44 | BI83: 45 | BJ83: 46 | BK83: 6 | BL83: 6 | BM83: 47 | BN83: 48 | BO83: 49 | BP83: 50 | BQ83: 51 | BR83: 52 | BS83: 53 | BT83: 54 | BU83: 55 | BV83: 56 | BW83: 57 | BX83: 58 | BY83: 59 | BZ83: 60 | CA83: 61 | CB83: 62
T84: von | U84: bis | V84: Jan | W84: Feb | X84: Mrz | Y84: Apr | Z84: Mai | AA84: Jun | AB84: Jul | AC84: Aug | AD84: Sep | AE84: Okt | AF84: Nov | AG84: Dez | AH84: AP | AP84: von | AQ84: bis | AR84: Jan | AS84: Feb | AT84: Mrz | AU84: Apr | AV84: Mai | AW84: Jun | AX84: Jul | AY84: Aug | AZ84: Sep | BA84: Okt | BB84: Nov | BC84: Dez | BD84: AP | BL84: von | BM84: bis | BN84: Jan | BO84: Feb | BP84: Mrz | BQ84: Apr | BR84: Mai | BS84: Jun | BT84: Jul | BU84: Aug | BV84: Sep | BW84: Okt | BX84: Nov | BY84: Dez | BZ84: AP
V85: =V6 -> 44927 | W85: =W6 -> 44958 | X85: =X6 -> 44986 | Y85: =Y6 -> 45017 | Z85: =Z6 -> 45047 | AA85: =AA6 -> 45078 | AB85: =AB6 -> 45108 | AC85: =AC6 -> 45139 | ... AG85: =AG6 -> 45261 | AR85: =AR6 -> 45412 | AS85: =AS6 -> 45443 | AT85: =AT6 -> 45472 | AU85: =AU6 -> 45503 | AV85: =AV6 -> 45533 | AW85: =AW6 -> 45564 | AX85: =AX6 -> 45594 | AY85: =AY6 -> 45625 | ... BC85: =BC6 -> 45747 | BN85: =BN6 | BO85: =BO6 -> #VALUE! | BP85: =BP6 -> #VALUE! | BQ85: =BQ6 -> #VALUE! | BR85: =BR6 -> #VALUE! | BS85: =BS6 -> #VALUE! | BT85: =BT6 -> #VALUE! | BU85: =BU6 -> #VALUE! | ... BY85: =BY6 -> #VALUE! | BZ85: =$A7 -> 0
T86: =$D8 -> 45047 | U86: =$E8 -> 45077 | V86: =V8 | W86: =W8 | X86: =X8 | Y86: =Y8 | Z86: =Z8 -> x | AA86: =AA8 | AB86: =AB8 | AC86: =AC8 | ... AG86: =AG8 | AH86: =$A8 -> 1 | AP86: =$AI8 -> 0 | AQ86: =$AJ8 -> 0 | AR86: =AR8 | AS86: =AS8 | AT86: =AT8 | AU86: =AU8 | AV86: =AV8 | AW86: =AW8 | AX86: =AX8 | AY86: =AY8 | ... BC86: =BC8 | BD86: =$A8 -> 1 | BL86: =$BE8 -> 0 | BM86: =$BF8 -> 0 | BN86: =BN8 -> x | BO86: =BO8 -> #VALUE! | BP86: =BP8 -> #VALUE! | BQ86: =BQ8 -> #VALUE! | BR86: =BR8 -> #VALUE! | BS86: =BS8 -> #VALUE! | BT86: =BT8 -> #VALUE! | BU86: =BU8 -> #VALUE! | ... BY86: =BY8 -> #VALUE! | BZ86: =$A8 -> 1
T87: =$D9 -> 45047 | U87: =$E9 -> 45077 | V87: =V9 | W87: =W9 | X87: =X9 | Y87: =Y9 | Z87: =Z9 -> x | AA87: =AA9 | AB87: =AB9 | AC87: =AC9 | ... AG87: =AG9 | AH87: =$A9 -> 2.1 | AP87: =$AI9 -> 0 | AQ87: =$AJ9 -> 0 | AR87: =AR9 | AS87: =AS9 | AT87: =AT9 | AU87: =AU9 | AV87: =AV9 | AW87: =AW9 | AX87: =AX9 | AY87: =AY9 | ... BC87: =BC9 | BD87: =$A9 -> 2.1 | BL87: =$BE9 -> 0 | BM87: =$BF9 -> 0 | BN87: =BN9 -> x | BO87: =BO9 -> #VALUE! | BP87: =BP9 -> #VALUE! | BQ87: =BQ9 -> #VALUE! | BR87: =BR9 -> #VALUE! | BS87: =BS9 -> #VALUE! | BT87: =BT9 -> #VALUE! | BU87: =BU9 -> #VALUE! | ... BY87: =BY9 -> #VALUE! | BZ87: =$A9 -> 2.1
...

Sheet Planung Personal
A2: Jahresvorkalkulation Personalkosten
A4: =Nav!H16 -> 45047 | B4: =Nav!H16 -> 45047
B5: Name MA | D5: Monat
C6: tech-nisch | D6: =DATE(YEAR(B4),1,1) -> 44927 | E6: =D6+31 -> 44958 | F6: =IF((MOD(YEAR(E6),4)=0)-(MOD(YEAR(E6),100)=0)+(MOD(YEAR(E6),400)=0)=0,E6+28,E6+29) -> 44986 | G6: =F6+31 -> 45017 | H6: =G6+30 -> 45047 | I6: =H6+31 -> 45078 | J6: =I6+30 -> 45108 | K6: =J6+31 -> 45139 | L6: =K6+31 -> 45170 | M6: =L6+30 -> 45200 | N6: =M6+31 -> 45231 | O6: =N6+30 -> 45261 | P6: Summe PM/MA | R6: Kategorie bzw. Personalqualifikation | S6: Vorkalkulierter Personaleinsatz (Stunden) | T6: Jahresbruttogehalt | U6: Wochenarbeits-stunden | V6: Jahresarbeits-stunden | W6: Stundensatz | X6: Einzelkosten | Y6: Zuschlagsatz in % | Z6: Zuschlag | AA6: Gesamt
R7: Gehälter
B9: =Nav!B32 -> Tippl, Mario | C9: x | I9: 0.5 | J9: 0.5 | K9: 0.5 | L9: 0.5 | M9: 0.5 | P9: =SUM(D9:O9) -> 2.5 | R9: =$B$9 -> Tippl, Mario | S9: =(P9*V9/12) -> 433.33333 | T9: =10000*12 -> 120000 | U9: 40 | V9: =U9*52 -> 2080 | W9: =IF(V9=0,"0,00 €",ROUND(T9/V9,2)) -> 57.69 | X9: =(S9*W9) -> 24999 | Y9: =Nav!$M$12 -> 0.2842 | Z9: =ROUND(X9*Y9,2) -> 7104.72 | AA9: =Z9+X9 -> 32103.72
H10: 0.5 | N10: 0.5 | O10: 0.5 | P10: =SUM(D10:O10) -> 1.5 | S10: =(P10*V9/12) -> 260 | X10: =(S10*W9) -> 14999.4 | Y10: =Nav!$M$13 -> 0.2988 | Z10: =ROUND(X10*Y10,2) -> 4481.82 | AA10: =Z10+X10 -> 19481.22
B11: =Nav!B33 -> Socha, Pawel | C11: x | J11: 0.5 | K11: 0.5 | P11: =SUM(D11:O11) -> 1 | R11: =$B$11 -> Socha, Pawel | S11: =(P11*V11/12) -> 173.33333 | T11: =3225*12 -> 38700 | U11: 40 | V11: =U11*52 -> 2080 | W11: =IF(V11=0,"0,00 €",ROUND(T11/V11,2)) -> 18.61 | X11: =(S11*W11) -> 3225.7333 | Y11: =Nav!$M$12 -> 0.2842 | Z11: =ROUND(X11*Y11,2) -> 916.75 | AA11: =Z11+X11 -> 4142.4833
H12: 0.5 | P12: =SUM(D12:O12) -> 0.5 | S12: =(P12*V11/12) -> 86.666667 | X12: =(S12*W11) -> 1612.8667 | Y12: =Nav!$M$13 -> 0.2988 | Z12: =ROUND(X12*Y12,2) -> 481.92 | AA12: =Z12+X12 -> 2094.7867
B13: =Nav!B34 -> Tippl, Karen | C13: x | I13: 0.5 | J13: 0.5 | K13: 0.5 | L13: 0.5 | M13: 0.5 | P13: =SUM(D13:O13) -> 2.5 | R13: =$B$13 -> Tippl, Karen | S13: =(P13*V13/12) -> 216.66667 | T13: =2975*12 -> 35700 | U13: 20 | V13: =U13*52 -> 1040 | W13: =IF(V13=0,"0,00 €",ROUND(T13/V13,2)) -> 34.33 | X13: =(S13*W13) -> 7438.1667 | Y13: =Nav!$M$12 -> 0.2842 | Z13: =ROUND(X13*Y13,2) -> 2113.93 | AA13: =Z13+X13 -> 9552.0967
P14: =SUM(D14:O14) -> 0 | S14: =(P14*V13/12) -> 0 | X14: =(S14*W13) -> 0 | Y14: =Nav!$M$13 -> 0.2988 | Z14: =ROUND(X14*Y14,2) -> 0 | AA14: =Z14+X14 -> 0
B15: =Nav!B35 -> MA 4 | C15: x | P15: =SUM(D15:O15) -> 0 | R15: =$B$15 -> MA 4 | S15: =(P15*V15/12) -> 0 | V15: =U15*52 -> 0 | W15: =IF(V15=0,"0,00 €",ROUND(T15/V15,2)) -> 0,00 € | X15: =(S15*W15) -> 0 | Y15: =Nav!$M$12 -> 0.2842 | Z15: =ROUND(X15*Y15,2) -> 0 | AA15: =Z15+X15 -> 0
P16: =SUM(D16:O16) -> 0 | S16: =(P16*V15/12) -> 0 | X16: =(S16*W15) -> 0 | Y16: =Nav!$M$13 -> 0.2988 | Z16: =ROUND(X16*Y16,2) -> 0 | AA16: =Z16+X16 -> 0
B17: =Nav!B36 -> MA 5 | C17: x | P17: =SUM(D17:O17) -> 0 | R17: =$B$17 -> MA 5 | S17: =(P17*V17/12) -> 0 | V17: =U17*52 -> 0 | W17: =IF(V17=0,"0,00 €",ROUND(T17/V17,2)) -> 0,00 € | X17: =(S17*W17) -> 0 | Y17: =Nav!$M$12 -> 0.2842 | Z17: =ROUND(X17*Y17,2) -> 0 | AA17: =Z17+X17 -> 0
P18: =SUM(D18:O18) -> 0 | S18: =(P18*V17/12) -> 0 | X18: =(S18*W17) -> 0 | Y18: =Nav!$M$13 -> 0.2988 | Z18: =ROUND(X18*Y18,2) -> 0 | AA18: =Z18+X18 -> 0
P19: =SUM(P9:P17) -> 8 | Z19: Summe | AA19: =SUM(AA9:AA17) -> 67374.307
Z20: Förderquote | AA20: =Nav!$K$6 -> 0.7
Y21: Fördersumme Personal | AA21: =AA19*AA20 -> 47162.015
A23: =Nav!H17 | B23: =Nav!H17
B24: Name MA | D24: Monat
D25: =B23 | E25: =D25+31 -> #VALUE! | F25: =IF((MOD(YEAR(E25),4)=0)-(MOD(YEAR(E25),100)=0)+(MOD(YEAR(E25),400)=0)=0,E25+28,E25+29) -> #VALUE! | G25: =F25+31 -> #VALUE! | H25: =G25+30 -> #VALUE! | I25: =H25+31 -> #VALUE! | J25: =I25+30 -> #VALUE! | K25: =J25+31 -> #VALUE! | L25: =K25+31 -> #VALUE! | M25: =L25+30 -> #VALUE! | N25: =M25+31 -> #VALUE! | O25: =N25+30 -> #VALUE! | P25: Summe PM/MA | R25: Kategorie bzw. Personalqualifikation | S25: Vorkalkulierter Personaleinsatz (Stunden) | T25: Jahresbruttogehalt | U25: Wochenarbeits-stunden | V25: Jahresarbeits-stunden | W25: Stundensatz | X25: Einzelkosten | Y25: Zuschlagsatz in % | Z25: Zuschlag | AA25: Gesamt
R26: Gehälter
B28: =$B$9 -> Tippl, Mario | P28: =SUM(D28:O28) -> 0 | R28: =$B$9 -> Tippl, Mario | S28: =(P28*V28/12) -> 0 | T28: =T9 -> 120000 | U28: =U9 -> 40 | V28: =V9 -> 2080 | W28: =IF(V28=0, "0,00 €", (T28/V28)) -> 57.692308 | X28: =(S28*W28) -> 0 | Y28: =Nav!$M$12 -> 0.2842 | Z28: =(X28*Y28) -> 0 | AA28: =Z28+X28 -> 0
